Workbook

Sheet Demonstrativo
A1: Demosntrativo de Faturamento (Valores com formulas - não alterar)
B3: Janeiro | C3: Fevereiro | D3: Março | E3: Abril | F3: Maio | G3: Junho | H3: Julho | I3: Agosto | J3: Setembro | K3: Outubro | L3: Novembro | M3: Dezembro
A4: ='Dezembro 2026'!W3 -> Faturamento | B4: =Janeiro.2026!X3 -> 0 | C4: ='Fevereiro 2026'!X3 -> 0 | D4: ='Março 2026'!X3 -> 0 | E4: ='Abril 2026'!X3 -> 0 | F4: ='Maio 2026'!X3 -> 0 | G4: ='Junho 2026'!X3 -> 0 | H4: ='Julho 2026'!X3 -> 0 | I4: ='Agosto 2026'!X3 -> 0 | J4: ='Setembro 2026'!X3 -> 0 | K4: ='Outubro 2026'!X3 -> 0 | L4: ='Novembro 2026'!X3 -> 0 | M4: ='Dezembro 2026'!X3 -> 0
A5: ='Dezembro 2026'!W4 -> Aliquota de Imposto | B5: =Janeiro.2026!X4 -> 0.04 | C5: ='Fevereiro 2026'!X4 -> 0.04 | D5: ='Março 2026'!X4 -> 0.04 | E5: ='Abril 2026'!X4 -> 0.04 | F5: ='Maio 2026'!X4 -> 0.04 | G5: ='Junho 2026'!X4 -> 0.04 | H5: ='Julho 2026'!X4 -> 0.04 | I5: ='Agosto 2026'!X4 -> 0.04 | J5: ='Setembro 2026'!X4 -> 0.04 | K5: ='Outubro 2026'!X4 -> 0.04 | L5: ='Novembro 2026'!X4 -> 0.04 | M5: ='Dezembro 2026'!X4 -> 0.04
A6: ='Dezembro 2026'!W8 -> ticket médio mensal | B6: =Janeiro.2026!X13 -> 0 | C6: ='Fevereiro 2026'!X8 -> 0 | D6: ='Março 2026'!X8 -> 0 | E6: ='Abril 2026'!X8 -> 0 | F6: ='Maio 2026'!X8 -> 0 | G6: ='Junho 2026'!X8 -> 0 | H6: ='Julho 2026'!X8 -> 0 | I6: ='Agosto 2026'!X8 -> 0 | J6: ='Setembro 2026'!X7 -> 0 | K6: ='Outubro 2026'!X8 -> 0 | L6: ='Novembro 2026'!X8 -> 0 | M6: ='Dezembro 2026'!X8 -> 0
A7: ='Dezembro 2026'!W5 -> Total Gasto em armazenagem | B7: =Janeiro.2026!X5 -> 0 | C7: ='Fevereiro 2026'!X5 -> 0 | D7: ='Março 2026'!X5 -> 0 | E7: ='Abril 2026'!X5 -> 0 | F7: ='Maio 2026'!X5 -> 0 | G7: ='Junho 2026'!X5 -> 0 | H7: ='Julho 2026'!X5 -> 0 | I7: ='Agosto 2026'!X5 -> 0 | J7: ='Setembro 2026'!X5 -> 0 | K7: ='Outubro 2026'!X5 -> 0 | L7: ='Novembro 2026'!X5 -> 0 | M7: ='Dezembro 2026'!X5 -> 0
A8: ='Dezembro 2026'!W6 -> Ads Mercado Livre | B8: =Janeiro.2026!X6 -> 0 | C8: ='Fevereiro 2026'!X6 -> 0 | D8: ='Março 2026'!X6 -> 0 | E8: ='Abril 2026'!X6 -> 0 | F8: ='Maio 2026'!X6 -> 0 | G8: ='Junho 2026'!X6 -> 0 | H8: ='Julho 2026'!X6 -> 0 | I8: ='Agosto 2026'!X6 -> 0 | J8: ='Setembro 2026'!X6 -> 0 | K8: ='Outubro 2026'!X6 -> 0 | L8: ='Novembro 2026'!X6 -> 0 | M8: ='Dezembro 2026'!X6 -> 0
A9: ='Dezembro 2026'!W7 -> Ads Outras Plataformas avulsas | B9: =Janeiro.2026!X7 -> 0 | C9: ='Fevereiro 2026'!X7 -> 0 | D9: ='Março 2026'!X7 -> 0 | E9: ='Abril 2026'!X7 -> 0 | F9: ='Maio 2026'!X7 -> 0 | G9: ='Junho 2026'!X7 -> 0 | H9: ='Julho 2026'!X7 -> 0 | I9: ='Agosto 2026'!X7 -> 0 | J9: ='Setembro 2026'!X7 -> 0 | K9: ='Outubro 2026'!X7 -> 0 | L9: ='Novembro 2026'!X7 -> 0 | M9: ='Dezembro 2026'!X7 -> 0
A10: ='Dezembro 2026'!W9 -> Custo com Produtos | B10: =Janeiro.2026!X8 -> 0 | C10: ='Fevereiro 2026'!X9 -> 0 | D10: ='Março 2026'!X9 -> 0 | E10: ='Abril 2026'!X9 -> 0 | F10: ='Maio 2026'!X9 -> 0 | G10: ='Junho 2026'!X9 -> 0 | H10: ='Julho 2026'!X9 -> 0 | I10: ='Agosto 2026'!X9 -> 0 | J10: ='Setembro 2026'!X9 -> 0 | K10: ='Outubro 2026'!X9 -> 0 | L10: ='Novembro 2026'!X9 -> 0 | M10: ='Dezembro 2026'!X9 -> 0
A11: ='Dezembro 2026'!W10 -> Tarifas Marketplaces | B11: =Janeiro.2026!X9 -> 0 | C11: ='Fevereiro 2026'!X10 -> 0 | D11: ='Março 2026'!X10 -> 0 | E11: ='Abril 2026'!X10 -> 0 | F11: ='Maio 2026'!X12 -> 0 | G11: ='Junho 2026'!X10 -> 0 | H11: ='Julho 2026'!X10 -> 0 | I11: ='Agosto 2026'!X10 -> 0 | J11: ='Setembro 2026'!X10 -> 0 | K11: ='Outubro 2026'!X10 -> 0 | L11: ='Novembro 2026'!X10 -> 0 | M11: ='Dezembro 2026'!X10 -> 0
A12: Frete | B12: =Janeiro.2026!X10 -> 0 | C12: ='Fevereiro 2026'!X11 -> 0 | D12: ='Março 2026'!X11 -> 0 | E12: ='Abril 2026'!X11 -> 0 | F12: ='Maio 2026'!X11 -> 0 | G12: ='Junho 2026'!X11 -> 0 | H12: ='Julho 2026'!X11 -> 0 | I12: ='Agosto 2026'!X11 -> 0 | J12: ='Setembro 2026'!X11 -> 0 | K12: ='Outubro 2026'!X11 -> 0 | L12: ='Novembro 2026'!X11 -> 0 | M12: ='Dezembro 2026'!X11 -> 0
A13: ='Dezembro 2026'!W12 -> Imposto - DAS | B13: =Janeiro.2026!X11 -> 0 | C13: ='Fevereiro 2026'!X12 -> 0 | D13: ='Março 2026'!X12 -> 0 | E13: ='Abril 2026'!X12 -> 0 | F13: ='Maio 2026'!X12 -> 0 | G13: ='Junho 2026'!X12 -> 0 | H13: ='Julho 2026'!X12 -> 0 | I13: ='Agosto 2026'!X12 -> 0 | J13: ='Setembro 2026'!X12 -> 0 | K13: ='Outubro 2026'!X12 -> 0 | L13: ='Novembro 2026'!X12 -> 0 | M13: ='Dezembro 2026'!X12 -> 0
A14: ='Dezembro 2026'!W14 -> Outras Taxas | B14: =Janeiro.2026!X12 -> 0 | C14: ='Fevereiro 2026'!X14 -> 0 | D14: ='Março 2026'!X14 -> 0 | E14: ='Abril 2026'!X14 -> 0 | F14: ='Maio 2026'!X14 -> 0 | G14: ='Junho 2026'!X14 -> 0 | H14: ='Julho 2026'!X14 -> 0 | I14: ='Agosto 2026'!X14 -> 0 | J14: ='Setembro 2026'!X14 -> 0 | K14: ='Outubro 2026'!X14 -> 0 | L14: ='Novembro 2026'!X14 -> 0 | M14: ='Dezembro 2026'!X14 -> 0
A15: ='Dezembro 2026'!W13 -> Página Oficial Mercado Livre | B15: =Janeiro.2026!X14 -> 0 | C15: ='Fevereiro 2026'!X13 -> 0 | D15: ='Março 2026'!X13 -> 0 | E15: ='Abril 2026'!X13 -> 0 | F15: ='Maio 2026'!X13 -> 0 | G15: ='Junho 2026'!X13 -> 0 | H15: ='Julho 2026'!X13 -> 0 | I15: ='Agosto 2026'!X13 -> 0 | J15: ='Setembro 2026'!X13 -> 0 | K15: ='Outubro 2026'!X13 -> 0 | L15: ='Novembro 2026'!X13 -> 0 | M15: ='Dezembro 2026'!X13 -> 0
A16: ='Dezembro 2026'!W15 -> INSS | B16: =Janeiro.2026!X15 -> 0 | C16: ='Fevereiro 2026'!X15 -> 0 | D16: ='Março 2026'!X15 -> 0 | E16: ='Abril 2026'!X15 -> 0 | F16: ='Maio 2026'!X15 -> 0 | G16: ='Junho 2026'!X15 -> 0 | H16: ='Julho 2026'!X14 -> 0 | I16: ='Agosto 2026'!X15 -> 0 | J16: ='Setembro 2026'!X14 -> 0 | K16: ='Outubro 2026'!X15 -> 0 | L16: ='Novembro 2026'!X15 -> 0 | M16: ='Dezembro 2026'!X15 -> 0
A17: ='Dezembro 2026'!W16 -> Contabilidade | B17: =Janeiro.2026!X16 -> 0 | C17: ='Fevereiro 2026'!X16 -> 0 | D17: ='Março 2026'!X16 -> 0 | E17: ='Abril 2026'!X16 -> 0 | F17: ='Maio 2026'!X16 -> 0 | G17: ='Junho 2026'!X16 -> 0 | H17: ='Julho 2026'!X16 -> 0 | I17: ='Agosto 2026'!X16 -> 0 | J17: ='Setembro 2026'!X16 -> 0 | K17: ='Outubro 2026'!X16 -> 0 | L17: ='Novembro 2026'!X16 -> 0 | M17: ='Dezembro 2026'!X16 -> 0
A18: ='Dezembro 2026'!W17 -> Empréstimo | B18: =Janeiro.2026!X17 -> 0 | C18: ='Fevereiro 2026'!X17 -> 0 | D18: ='Março 2026'!X17 -> 0 | E18: ='Abril 2026'!X17 -> 0 | F18: ='Maio 2026'!X17 -> 0 | G18: ='Junho 2026'!X17 -> 0 | H18: ='Julho 2026'!X17 -> 0 | I18: ='Agosto 2026'!X17 -> 0 | J18: ='Setembro 2026'!X17 -> 0 | K18: ='Outubro 2026'!X17 -> 0 | L18: ='Novembro 2026'!X17 -> 0 | M18: ='Dezembro 2026'!X17 -> 0
A19: ='Dezembro 2026'!W18 -> Pró Labore | B19: =Janeiro.2026!X18 -> 0 | C19: ='Fevereiro 2026'!X18 -> 0 | D19: ='Março 2026'!X18 -> 0 | E19: ='Abril 2026'!X18 -> 0 | F19: ='Maio 2026'!X18 -> 0 | G19: ='Junho 2026'!X18 -> 0 | H19: ='Julho 2026'!X18 -> 0 | I19: ='Agosto 2026'!X18 -> 0 | J19: ='Setembro 2026'!X18 -> 0 | K19: ='Outubro 2026'!X18 -> 0 | L19: ='Novembro 2026'!X18 -> 0 | M19: ='Dezembro 2026'!X18 -> 0
A20: ='Dezembro 2026'!W19 -> Previdência Privada | B20: =Janeiro.2026!X19 -> 0 | C20: ='Fevereiro 2026'!X19 -> 0 | D20: ='Março 2026'!X19 -> 0 | E20: ='Abril 2026'!X19 -> 0 | F20: ='Maio 2026'!X19 -> 0 | G20: ='Junho 2026'!X19 -> 0 | H20: ='Julho 2026'!X19 -> 0 | I20: ='Agosto 2026'!X19 -> 0 | J20: ='Setembro 2026'!X19 -> 0 | K20: ='Outubro 2026'!X19 -> 0 | L20: ='Novembro 2026'!X19 -> 0 | M20: ='Dezembro 2026'!X19 -> 0
A21: ERP Mensal | B21: =Janeiro.2026!X20 -> 0 | C21: ='Fevereiro 2026'!X20 -> 0 | D21: ='Março 2026'!X20 -> 0 | E21: ='Abril 2026'!X20 -> 0 | F21: ='Maio 2026'!X20 -> 0 | G21: ='Junho 2026'!X20 -> 0 | H21: ='Julho 2026'!X20 -> 0 | I21: ='Agosto 2026'!X20 -> 0 | J21: ='Setembro 2026'!X20 -> 0 | K21: ='Outubro 2026'!X20 -> 0 | L21: ='Novembro 2026'!X20 -> 0 | M21: ='Dezembro 2026'!X20 -> 0
A22: Lucro Bruto | B22: =Janeiro.2026!X21 -> 0 | C22: ='Fevereiro 2026'!X21 -> 0 | D22: ='Março 2026'!X21 -> 0 | E22: ='Abril 2026'!X21 -> 0 | F22: ='Maio 2026'!X21 -> 0 | G22: ='Junho 2026'!X21 -> 0 | H22: ='Julho 2026'!X21 -> 0 | I22: ='Agosto 2026'!X21 -> 0 | J22: ='Setembro 2026'!X21 -> 0 | K22: ='Outubro 2026'!X21 -> 0 | L22: ='Novembro 2026'!X21 -> 0 | M22: ='Dezembro 2026'!X21 -> 0
A24: Break-Even Point - Mensal | B24: =IFERROR((ABS(SUM(B15:B20)) / ((B4 - ABS(SUM(B7:B14))) / B4)), "") | C24: =IFERROR((ABS(SUM(C15:C20)) / ((C4 - ABS(SUM(C7:C14))) / C4)), "") | D24: =IFERROR((ABS(SUM(D15:D20)) / ((D4 - ABS(SUM(D7:D14))) / D4)), "") | E24: =IFERROR((ABS(SUM(E15:E20)) / ((E4 - ABS(SUM(E7:E14))) / E4)), "") | F24: =IFERROR((ABS(SUM(F15:F20)) / ((F4 - ABS(SUM(F7:F14))) / F4)), "") | G24: =IFERROR((ABS(SUM(G15:G20)) / ((G4 - ABS(SUM(G7:G14))) / G4)), "") | H24: =IFERROR((ABS(SUM(H15:H20)) / ((H4 - ABS(SUM(H7:H14))) / H4)), "") | I24: =IFERROR((ABS(SUM(I15:I20)) / ((I4 - ABS(SUM(I7:I14))) / I4)), "") | ... M24: =IFERROR((ABS(SUM(M15:M20)) / ((M4 - ABS(SUM(M7:M14))) / M4)), "")
A25: Break-Even Point - Média | B25: =AVERAGE(B24:M24) -> #DIV/0!
A27: Fatura Mercado Livre | B27: =Janeiro.2026!X24 -> 0 | C27: ='Fevereiro 2026'!X24 -> 0 | D27: ='Março 2026'!X23 -> 0 | E27: ='Abril 2026'!X23 -> 0 | F27: ='Maio 2026'!X23 -> 0 | G27: ='Junho 2026'!X23 -> 0 | H27: ='Julho 2026'!X23 -> 0 | I27: ='Agosto 2026'!X23 -> 0 | J27: ='Setembro 2026'!X23 -> 0 | K27: ='Outubro 2026'!X23 -> 0 | L27: ='Novembro 2026'!X23 -> 0 | M27: ='Dezembro 2026'!X23 -> 0
A29: Margem de Contribuição | B29: =IFERROR(((B4+B7+B8+B9+B10+B11+B13+B14)/B4), "") | C29: =IFERROR(((C4+C7+C8+C9+C10+C11+C13+C14)/C4), "") | D29: =IFERROR(((D4+D7+D8+D9+D10+D11+D13+D14)/D4), "") | E29: =IFERROR(((E4+E7+E8+E9+E10+E11+E13+E14)/E4), "") | F29: =IFERROR(((F4+F7+F8+F9+F10+F11+F13+F14)/F4), "") | G29: =IFERROR(((G4+G7+G8+G9+G10+G11+G13+G14)/G4), "") | H29: =IFERROR(((H4+H7+H8+H9+H10+H11+H13+H14)/H4), "") | I29: =IFERROR(((I4+I7+I8+I9+I10+I11+I13+I14)/I4), "") | ... M29: =IFERROR(((M4+M7+M8+M9+M10+M11+M13+M14)/M4), "")
A31: DLR do Sócio | B31: =Janeiro.2026!X27 -> 0 | C31: ='Fevereiro 2026'!X27 -> 0 | D31: ='Março 2026'!X27 -> 0 | E31: ='Abril 2026'!X27 -> 0 | F31: ='Maio 2026'!X27 -> 0 | G31: ='Junho 2026'!X27 -> 0 | H31: ='Julho 2026'!X27 -> 0 | I31: ='Agosto 2026'!X27 -> 0 | J31: ='Setembro 2026'!X27 -> 0 | K31: ='Outubro 2026'!X27 -> 0 | L31: ='Novembro 2026'!X27 -> 0 | M31: ='Dezembro 2026'!X27 -> 0
A32: Reinvestimento - Empresa | B32: =Janeiro.2026!X28 -> 0 | C32: ='Fevereiro 2026'!X28 -> 0 | D32: ='Março 2026'!X28 -> 0 | E32: ='Abril 2026'!X28 -> 0 | F32: ='Maio 2026'!X28 -> 0 | G32: ='Junho 2026'!X28 -> 0 | H32: ='Julho 2026'!X28 -> 0 | I32: ='Agosto 2026'!X28 -> 0 | J32: ='Setembro 2026'!X28 -> 0 | K32: ='Outubro 2026'!X28 -> 0 | L32: ='Novembro 2026'!X28 -> 0 | M32: ='Dezembro 2026'!X28 -> 0
A35: Fechamento anual
A36: Faturamento | B36: =SUM(B4:M4) -> 0
A37: Publicidade | B37: =ABS(SUM(B8:M9)) -> 0
A38: Tarifa Market Place | B38: =ABS(SUM(B11:M11)) -> 0
A39: Frete | B39: =ABS(SUM(B12:M12)) -> 0
A40: Armazenamento | B40: =ABS(SUM(B7:M7)) -> 0
A41: Despesas Fixas | B41: =ABS(SUM(B15:M20)) -> 0
A42: Impostos DAS | B42: =ABS(SUM(B13:M13)) -> 0
A43: Lucro | B43: =SUM(B22:M22) -> 0

Sheet Faturamentos
A1: Faturamento de Anos Anteriores (Alterar somente células em branco) - Células em laranja são formulas
B3: 2023 | C3: 2024 | D3: 2025 | E3: 2026 | F3: 2025/2026
A4: Mês | B4: Faturamento (R$) | C4: Faturamento (R$) | D4: Faturamento (R$) | E4: Faturamento (R$) | F4: Crescimento
A5: Janeiro | E5: =Janeiro.2026!X3 -> 0 | F5: =IFERROR(ABS((100%-(E5/D5))), "")
A6: Fevereiro | E6: ='Fevereiro 2026'!X3 -> 0 | F6: =IFERROR(ABS((100%-(E6/D6))), "")
A7: Março | E7: ='Março 2026'!X3 -> 0 | F7: =IFERROR(ABS((100%-(E7/D7))), "")
A8: Abril | E8: ='Abril 2026'!X3 -> 0 | F8: =IFERROR(ABS((100%-(E8/D8))), "")
A9: Maio | E9: ='Maio 2026'!X3 -> 0 | F9: =IFERROR(ABS((100%-(E9/D9))), "")
A10: Junho | E10: ='Junho 2026'!X3 -> 0 | F10: =IFERROR(ABS((100%-(E10/D10))), "")
A11: Julho | E11: ='Julho 2026'!X3 -> 0 | F11: =IFERROR(ABS((100%-(E11/D11))), "")
A12: Agosto | E12: ='Agosto 2026'!X3 -> 0 | F12: =IFERROR(ABS((100%-(E12/D12))), "")
A13: Setembro | E13: ='Setembro 2026'!X3 -> 0 | F13: =IFERROR(ABS((100%-(E13/D13))), "")
A14: Outubro | E14: ='Outubro 2026'!X3 -> 0 | F14: =IFERROR(ABS((100%-(E14/D14))), "")
A15: Novembro | E15: ='Novembro 2026'!X3 -> 0 | F15: =IFERROR(ABS((100%-(E15/D15))), "")
A16: Dezembro | E16: ='Dezembro 2026'!X3 -> 0 | F16: =IFERROR(ABS((100%-(E16/D16))), "")
F18: % Atingido Relação ao Ano Anterior
A19: Faturamento | B19: =SUM(B5:B16) -> 0 | C19: =SUM(C5:C16) -> 0 | D19: =SUM(D5:D16) -> 0 | E19: =SUM(E5:E16) -> 0 | F19: =100%-(D19/E19) -> #DIV/0!
A21: Objetivo em relação ao a.a | B21: 0.3
A22: Meta 2026 | B22: =(D19*B21)+D19 -> 0
A23: Atingido até o momento | B23: =E19 -> 0
A24: % Atingido da Meta | B24: =B23/B22 -> #DIV/0!

Sheet Janeiro.2026
A1: Controle Mensal - Janeiro 2026
X2: Previsto | Y2: Real
A3: Dia | B3: Armazenagem | C3: Mercado Livre | D3: Magalu | E3: Casas Bahia | F3: Amazon | G3: Shopee | H3: TikTok | I3: Presencial | J3: Ticket Médio | K3: Ads | L3: Custo | M3: Tarifa | N3: Frete | O3: Salário | P3: Empréstimo | Q3: Contabilidade | R3: ERP | S3: INSS | T3: Outras Taxas | U3: Lucro Real do dia | W3: Faturamento | X3: =SUM(C36:I36) -> 0 | Y3: =X3 -> 0 | AA3: ROAS Atual | AB3: Objetivo
A4: 30 | O4: =$X$18/30 -> 0 | P4: =$X$17/30 -> 0 | Q4: =$X$16/30 -> 0 | R4: =$X$20/30 -> 0 | S4: =$X$15/30 -> 0 | U4: =C4+B4+K4+L4+M4+O4+P4+Q4+R4+S4+T4+D4+E4+F4+G4+I4+H4 -> 0 | W4: Aliquota de Imposto | X4: 0.04 | Y4: =X4 -> 0.04 | AA4: =-(X3/(X6+X7)) -> #DIV/0! | AB4: =IF($AA$4 > 12, "⭐ Excelente", IF($AA$4 >= 6, "✅ Saudável", IF($AA$4 < 5, "🛑 Perigo", "⚠️ Atenção"))) -> #DIV/0!
A5: 31 | O5: =$X$18/30 -> 0 | P5: =$X$17/30 -> 0 | Q5: =$X$16/30 -> 0 | R5: =$X$20/30 -> 0 | S5: =$X$15/30 -> 0 | U5: =C5+B5+K5+L5+M5+O5+P5+Q5+R5+S5+T5+D5+E5+F5+G5+I5+H5 -> 0 | W5: Total Gasto em armazenagem | X5: =SUM(B4:B34) -> 0 | Y5: =X5 -> 0
A6: 1 | O6: =$X$18/30 -> 0 | P6: =$X$17/30 -> 0 | Q6: =$X$16/30 -> 0 | R6: =$X$20/30 -> 0 | S6: =$X$15/30 -> 0 | U6: =C6+B6+K6+L6+M6+O6+P6+Q6+R6+S6+T6+D6+E6+F6+G6+I6+H6 -> 0 | W6: Ads Mercado Livre | X6: =SUM(K4:K34) -> 0 | Y6: =X6 -> 0 | AA6: Break-Even Point | AB6: =IFERROR(ABS(SUM(X14:X20)) / ((X3 - ABS(SUM(X5:X12))) / X3), "")
A7: 2 | O7: =$X$18/30 -> 0 | P7: =$X$17/30 -> 0 | Q7: =$X$16/30 -> 0 | R7: =$X$20/30 -> 0 | S7: =$X$15/30 -> 0 | U7: =C7+B7+K7+L7+M7+O7+P7+Q7+R7+S7+T7+D7+E7+F7+G7+I7+H7 -> 0 | W7: Ads Outras Plataformas avulsas | X7: 0 | Y7: =X7 -> 0
A8: 3 | O8: =$X$18/30 -> 0 | P8: =$X$17/30 -> 0 | Q8: =$X$16/30 -> 0 | R8: =$X$20/30 -> 0 | S8: =$X$15/30 -> 0 | U8: =C8+B8+K8+L8+M8+O8+P8+Q8+R8+S8+T8+D8+E8+F8+G8+I8+H8 -> 0 | W8: Custo com Produtos | X8: =SUM(L4:L34) -> 0 | Y8: =X8 -> 0
A9: 4 | O9: =$X$18/30 -> 0 | P9: =$X$17/30 -> 0 | Q9: =$X$16/30 -> 0 | R9: =$X$20/30 -> 0 | S9: =$X$15/30 -> 0 | U9: =C9+B9+K9+L9+M9+O9+P9+Q9+R9+S9+T9+D9+E9+F9+G9+I9+H9 -> 0 | W9: Tarifas Marketplaces | X9: =SUM(M4:M34) -> 0 | Y9: =X9 -> 0
A10: 5 | O10: =$X$18/30 -> 0 | P10: =$X$17/30 -> 0 | Q10: =$X$16/30 -> 0 | R10: =$X$20/30 -> 0 | S10: =$X$15/30 -> 0 | U10: =C10+B10+K10+L10+M10+O10+P10+Q10+R10+S10+T10+D10+E10+F10+G10+I10+H10 -> 0 | W10: Frete | X10: =SUM(N4:N34) -> 0 | Y10: 0
A11: 6 | O11: =$X$18/30 -> 0 | P11: =$X$17/30 -> 0 | Q11: =$X$16/30 -> 0 | R11: =$X$20/30 -> 0 | S11: =$X$15/30 -> 0 | U11: =C11+B11+K11+L11+M11+O11+P11+Q11+R11+S11+T11+D11+E11+F11+G11+I11+H11 -> 0 | W11: Imposto - DAS | X11: =X3*X4 -> 0 | Y11: -3486.87
A12: 7 | O12: =$X$18/30 -> 0 | P12: =$X$17/30 -> 0 | Q12: =$X$16/30 -> 0 | R12: =$X$20/30 -> 0 | S12: =$X$15/30 -> 0 | U12: =C12+B12+K12+L12+M12+O12+P12+Q12+R12+S12+T12+D12+E12+F12+G12+I12+H12 -> 0 | W12: Outras Taxas | X12: =SUM(T4:T34) -> 0 | Y12: =X12 -> 0
A13: 8 | O13: =$X$18/30 -> 0 | P13: =$X$17/30 -> 0 | Q13: =$X$16/30 -> 0 | R13: =$X$20/30 -> 0 | S13: =$X$15/30 -> 0 | U13: =C13+B13+K13+L13+M13+O13+P13+Q13+R13+S13+T13+D13+E13+F13+G13+I13+H13 -> 0 | W13: ticket médio mensal | X13: =(SUM(J4:J34))/31 -> 0 | Y13: =X13 -> 0
A14: 9 | O14: =$X$18/30 -> 0 | P14: =$X$17/30 -> 0 | Q14: =$X$16/30 -> 0 | R14: =$X$20/30 -> 0 | S14: =$X$15/30 -> 0 | U14: =C14+B14+K14+L14+M14+O14+P14+Q14+R14+S14+T14+D14+E14+F14+G14+I14+H14 -> 0 | W14: Página Oficial Mercado Livre | Y14: =X14 -> 0
A15: 10 | O15: =$X$18/30 -> 0 | P15: =$X$17/30 -> 0 | Q15: =$X$16/30 -> 0 | R15: =$X$20/30 -> 0 | S15: =$X$15/30 -> 0 | U15: =C15+B15+K15+L15+M15+O15+P15+Q15+R15+S15+T15+D15+E15+F15+G15+I15+H15 -> 0 | W15: INSS | Y15: =X15 -> 0
A16: 11 | O16: =$X$18/30 -> 0 | P16: =$X$17/30 -> 0 | Q16: =$X$16/30 -> 0 | R16: =$X$20/30 -> 0 | S16: =$X$15/30 -> 0 | U16: =C16+B16+K16+L16+M16+O16+P16+Q16+R16+S16+T16+D16+E16+F16+G16+I16+H16 -> 0 | W16: Contabilidade | Y16: =X16 -> 0
A17: 12 | O17: =$X$18/30 -> 0 | P17: =$X$17/30 -> 0 | Q17: =$X$16/30 -> 0 | R17: =$X$20/30 -> 0 | S17: =$X$15/30 -> 0 | U17: =C17+B17+K17+L17+M17+O17+P17+Q17+R17+S17+T17+D17+E17+F17+G17+I17+H17 -> 0 | W17: Empréstimo | Y17: =X17 -> 0
A18: 13 | O18: =$X$18/30 -> 0 | P18: =$X$17/30 -> 0 | Q18: =$X$16/30 -> 0 | R18: =$X$20/30 -> 0 | S18: =$X$15/30 -> 0 | U18: =C18+B18+K18+L18+M18+O18+P18+Q18+R18+S18+T18+D18+E18+F18+G18+I18+H18 -> 0 | W18: Pró Labore + Previdência | Y18: =X18 -> 0
A19: 14 | O19: =$X$18/30 -> 0 | P19: =$X$17/30 -> 0 | Q19: =$X$16/30 -> 0 | R19: =$X$20/30 -> 0 | S19: =$X$15/30 -> 0 | U19: =C19+B19+K19+L19+M19+O19+P19+Q19+R19+S19+T19+D19+E19+F19+G19+I19+H19 -> 0 | W19: Previdência Privada | X19: =(X18-X21)*14% -> 0 | Y19: =X19 -> 0
A20: 15 | O20: =$X$18/30 -> 0 | P20: =$X$17/30 -> 0 | Q20: =$X$16/30 -> 0 | R20: =$X$20/30 -> 0 | S20: =$X$15/30 -> 0 | U20: =C20+B20+K20+L20+M20+O20+P20+Q20+R20+S20+T20+D20+E20+F20+G20+I20+H20 -> 0 | W20: ERP Mensal | Y20: =X20 -> 0
A21: 16 | O21: =$X$18/30 -> 0 | P21: =$X$17/30 -> 0 | Q21: =$X$16/30 -> 0 | R21: =$X$20/30 -> 0 | S21: =$X$15/30 -> 0 | U21: =C21+B21+K21+L21+M21+O21+P21+Q21+R21+S21+T21+D21+E21+F21+G21+I21+H21 -> 0 | W21: Lucro Bruto | X21: =X3+X5+X6+X7+X8+X9+X11+X12+X14+X15++X16+X17+X18+X20 -> 0 | Y21: =Y3+Y5+Y6+Y7+Y8+Y9+Y11+Y12+Y14+Y15++Y16+Y17+Y18+Y20 -> -3486.87
A22: 17 | O22: =$X$18/30 -> 0 | P22: =$X$17/30 -> 0 | Q22: =$X$16/30 -> 0 | R22: =$X$20/30 -> 0 | S22: =$X$15/30 -> 0 | U22: =C22+B22+K22+L22+M22+O22+P22+Q22+R22+S22+T22+D22+E22+F22+G22+I22+H22 -> 0 | W22: Lucro Liquido | X22: =X3+X5+X6+X7+X8+X9+X11+X12+X14+X15+X16+X17+X18+X19+X20 -> 0 | Y22: =Y3+Y5+Y6+Y7+Y8+Y9+Y11+Y12+Y14+Y15+Y16+Y17+Y18+Y19+Y20 -> -3486.87
A23: 18 | O23: =$X$18/30 -> 0 | P23: =$X$17/30 -> 0 | Q23: =$X$16/30 -> 0 | R23: =$X$20/30 -> 0 | S23: =$X$15/30 -> 0 | U23: =C23+B23+K23+L23+M23+O23+P23+Q23+R23+S23+T23+D23+E23+F23+G23+I23+H23 -> 0
A24: 19 | O24: =$X$18/30 -> 0 | P24: =$X$17/30 -> 0 | Q24: =$X$16/30 -> 0 | R24: =$X$20/30 -> 0 | S24: =$X$15/30 -> 0 | U24: =C24+B24+K24+L24+M24+O24+P24+Q24+R24+S24+T24+D24+E24+F24+G24+I24+H24 -> 0 | W24: Fatura Mercado Livre | X24: =X6+X5+X12+X14 -> 0 | Y24: =Y6+Y5+Y12+Y14 -> 0
A25: 20 | O25: =$X$18/30 -> 0 | P25: =$X$17/30 -> 0 | Q25: =$X$16/30 -> 0 | R25: =$X$20/30 -> 0 | S25: =$X$15/30 -> 0 | U25: =C25+B25+K25+L25+M25+O25+P25+Q25+R25+S25+T25+D25+E25+F25+G25+I25+H25 -> 0
A26: 21 | O26: =$X$18/30 -> 0 | P26: =$X$17/30 -> 0 | Q26: =$X$16/30 -> 0 | R26: =$X$20/30 -> 0 | S26: =$X$15/30 -> 0 | U26: =C26+B26+K26+L26+M26+O26+P26+Q26+R26+S26+T26+D26+E26+F26+G26+I26+H26 -> 0
A27: 22 | O27: =$X$18/30 -> 0 | P27: =$X$17/30 -> 0 | Q27: =$X$16/30 -> 0 | R27: =$X$20/30 -> 0 | S27: =$X$15/30 -> 0 | U27: =C27+B27+K27+L27+M27+O27+P27+Q27+R27+S27+T27+D27+E27+F27+G27+I27+H27 -> 0 | W27: DLR - Sócio | X27: =X21*X30 -> 0 | Y27: =Y21*50% -> -1743.435
A28: 23 | O28: =$X$18/30 -> 0 | P28: =$X$17/30 -> 0 | Q28: =$X$16/30 -> 0 | R28: =$X$20/30 -> 0 | S28: =$X$15/30 -> 0 | U28: =C28+B28+K28+L28+M28+O28+P28+Q28+R28+S28+T28+D28+E28+F28+G28+I28+H28 -> 0 | W28: Reinvestimento - Empresa | X28: =X21*X31 -> 0 | Y28: =Y21*50% -> -1743.435
A29: 24 | O29: =$X$18/30 -> 0 | P29: =$X$17/30 -> 0 | Q29: =$X$16/30 -> 0 | R29: =$X$20/30 -> 0 | S29: =$X$15/30 -> 0 | U29: =C29+B29+K29+L29+M29+O29+P29+Q29+R29+S29+T29+D29+E29+F29+G29+I29+H29 -> 0
A30: 25 | O30: =$X$18/30 -> 0 | P30: =$X$17/30 -> 0 | Q30: =$X$16/30 -> 0 | R30: =$X$20/30 -> 0 | S30: =$X$15/30 -> 0 | U30: =C30+B30+K30+L30+M30+O30+P30+Q30+R30+S30+T30+D30+E30+F30+G30+I30+H30 -> 0 | W30: % DLR do Sócio | X30: 0.5
A31: 26 | O31: =$X$18/30 -> 0 | P31: =$X$17/30 -> 0 | Q31: =$X$16/30 -> 0 | R31: =$X$20/30 -> 0 | S31: =$X$15/30 -> 0 | U31: =C31+B31+K31+L31+M31+O31+P31+Q31+R31+S31+T31+D31+E31+F31+G31+I31+H31 -> 0 | W31: Reenvestimento na empresa | X31: 0.5
A32: 27 | O32: =$X$18/30 -> 0 | P32: =$X$17/30 -> 0 | Q32: =$X$16/30 -> 0 | R32: =$X$20/30 -> 0 | S32: =$X$15/30 -> 0 | U32: =C32+B32+K32+L32+M32+O32+P32+Q32+R32+S32+T32+D32+E32+F32+G32+I32+H32 -> 0
A33: 28 | O33: =$X$18/30 -> 0 | P33: =$X$17/30 -> 0 | Q33: =$X$16/30 -> 0 | R33: =$X$20/30 -> 0 | S33: =$X$15/30 -> 0 | U33: =C33+B33+K33+L33+M33+O33+P33+Q33+R33+S33+T33+D33+E33+F33+G33+I33+H33 -> 0 | Y33: Células que estão com formulas e não devem ser alteradas
A34: 29 | O34: =$X$18/30 -> 0 | P34: =$X$17/30 -> 0 | Q34: =$X$16/30 -> 0 | R34: =$X$20/30 -> 0 | S34: =$X$15/30 -> 0 | U34: =C34+B34+K34+L34+M34+O34+P34+Q34+R34+S34+T34+D34+E34+F34+G34+I34+H34 -> 0 | Y34: Células que devem ser imputados os valores manualmente
A36: Total | C36: =SUM(C4:C34) -> 0 | D36: =SUM(D4:D34) -> 0 | E36: =SUM(E4:E34) -> 0 | F36: =SUM(F4:F34) -> 0 | G36: =SUM(G4:G34) -> 0 | H36: =SUM(H4:H34) -> 0 | I36: =SUM(I4:I34) -> 0

Sheet Fevereiro 2026
A1: Controle Mensal - Fevereiro 2026
X2: Previsto | Y2: Real
A3: Dia | B3: Armazenagem | C3: Mercado Livre | D3: Magalu | E3: Casas Bahia | F3: Amazon | G3: Shopee | H3: TikTok | I3: Presencial | J3: Ticket Médio | K3: Ads | L3: Custo | M3: Tarifa | N3: Frete | O3: Salário | P3: Empréstimo | Q3: Contabilidade | R3: ERP | S3: INSS | T3: Outras Taxas | U3: Lucro Real do dia | W3: Faturamento | X3: =SUM(C35:I35) -> 0 | Y3: =X3 -> 0 | AA3: ROAS Atual | AB3: Objetivo
A4: 30 | O4: =$X$18/29 -> 0 | P4: =$X$17/29 -> 0 | Q4: =$X$16/29 -> 0 | R4: =$X$20/29 -> 0 | S4: =$X$15/29 -> 0 | U4: =C4+B4+K4+L4+M4+O4+P4+Q4+R4+S4+T4+D4+E4+F4+G4+I4+H4 -> 0 | W4: Aliquota de Imposto | X4: 0.04 | AA4: =-(X3/(X6+X7)) -> #DIV/0! | AB4: =IF($AA$4 > 12, "⭐ Excelente", IF($AA$4 >= 6, "✅ Saudável", IF($AA$4 < 5, "🛑 Perigo", "⚠️ Atenção"))) -> #DIV/0!
A5: 31 | O5: =$X$18/29 -> 0 | P5: =$X$17/29 -> 0 | Q5: =$X$16/29 -> 0 | R5: =$X$20/29 -> 0 | S5: =$X$15/29 -> 0 | U5: =C5+B5+K5+L5+M5+O5+P5+Q5+R5+S5+T5+D5+E5+F5+G5+I5+H5 -> 0 | W5: Total Gasto em armazenagem | X5: =SUM(B4:B33) -> 0
A6: 1 | O6: =$X$18/29 -> 0 | P6: =$X$17/29 -> 0 | Q6: =$X$16/29 -> 0 | R6: =$X$20/29 -> 0 | S6: =$X$15/29 -> 0 | U6: =C6+B6+K6+L6+M6+O6+P6+Q6+R6+S6+T6+D6+E6+F6+G6+I6+H6 -> 0 | W6: Ads Mercado Livre | X6: =SUM(K4:K33) -> 0 | AA6: Break-Even Point | AB6: =IFERROR(ABS(SUM(X14:X20)) / ((X3 - ABS(SUM(X5:X12))) / X3), "")
A7: 2 | O7: =$X$18/29 -> 0 | P7: =$X$17/29 -> 0 | Q7: =$X$16/29 -> 0 | R7: =$X$20/29 -> 0 | S7: =$X$15/29 -> 0 | U7: =C7+B7+K7+L7+M7+O7+P7+Q7+R7+S7+T7+D7+E7+F7+G7+I7+H7 -> 0 | W7: Ads Outras Plataformas avulsas
A8: 3 | O8: =$X$18/29 -> 0 | P8: =$X$17/29 -> 0 | Q8: =$X$16/29 -> 0 | R8: =$X$20/29 -> 0 | S8: =$X$15/29 -> 0 | U8: =C8+B8+K8+L8+M8+O8+P8+Q8+R8+S8+T8+D8+E8+F8+G8+I8+H8 -> 0 | W8: ticket médio mensal | X8: =(SUM(J4:J33))/31 -> 0 | Y8: =X8 -> 0
A9: 4 | O9: =$X$18/29 -> 0 | P9: =$X$17/29 -> 0 | Q9: =$X$16/29 -> 0 | R9: =$X$20/29 -> 0 | S9: =$X$15/29 -> 0 | U9: =C9+B9+K9+L9+M9+O9+P9+Q9+R9+S9+T9+D9+E9+F9+G9+I9+H9 -> 0 | W9: Custo com Produtos | X9: =SUM(L4:L33) -> 0 | Y9: =X9 -> 0
A10: 5 | O10: =$X$18/29 -> 0 | P10: =$X$17/29 -> 0 | Q10: =$X$16/29 -> 0 | R10: =$X$20/29 -> 0 | S10: =$X$15/29 -> 0 | U10: =C10+B10+K10+L10+M10+O10+P10+Q10+R10+S10+T10+D10+E10+F10+G10+I10+H10 -> 0 | W10: Tarifas Marketplaces | X10: =SUM(M4:M33) -> 0 | Y10: =X10 -> 0
A11: 6 | O11: =$X$18/29 -> 0 | P11: =$X$17/29 -> 0 | Q11: =$X$16/29 -> 0 | R11: =$X$20/29 -> 0 | S11: =$X$15/29 -> 0 | U11: =C11+B11+K11+L11+M11+O11+P11+Q11+R11+S11+T11+D11+E11+F11+G11+I11+H11 -> 0 | W11: Frete | X11: =SUM(N4:N33) -> 0 | Y11: 0
A12: 7 | O12: =$X$18/29 -> 0 | P12: =$X$17/29 -> 0 | Q12: =$X$16/29 -> 0 | R12: =$X$20/29 -> 0 | S12: =$X$15/29 -> 0 | U12: =C12+B12+K12+L12+M12+O12+P12+Q12+R12+S12+T12+D12+E12+F12+G12+I12+H12 -> 0 | W12: Imposto - DAS | X12: =-X3*X4 -> 0 | Y12: =X12 -> 0
A13: 8 | O13: =$X$18/29 -> 0 | P13: =$X$17/29 -> 0 | Q13: =$X$16/29 -> 0 | R13: =$X$20/29 -> 0 | S13: =$X$15/29 -> 0 | U13: =C13+B13+K13+L13+M13+O13+P13+Q13+R13+S13+T13+D13+E13+F13+G13+I13+H13 -> 0 | W13: Página Oficial Mercado Livre | Y13: =X13 -> 0
A14: 9 | O14: =$X$18/29 -> 0 | P14: =$X$17/29 -> 0 | Q14: =$X$16/29 -> 0 | R14: =$X$20/29 -> 0 | S14: =$X$15/29 -> 0 | U14: =C14+B14+K14+L14+M14+O14+P14+Q14+R14+S14+T14+D14+E14+F14+G14+I14+H14 -> 0 | W14: Outras Taxas | X14: =SUM(T4:T33) -> 0 | Y14: =X14 -> 0
A15: 10 | O15: =$X$18/29 -> 0 | P15: =$X$17/29 -> 0 | Q15: =$X$16/29 -> 0 | R15: =$X$20/29 -> 0 | S15: =$X$15/29 -> 0 | U15: =C15+B15+K15+L15+M15+O15+P15+Q15+R15+S15+T15+D15+E15+F15+G15+I15+H15 -> 0 | W15: INSS | Y15: =X15 -> 0
A16: 11 | O16: =$X$18/29 -> 0 | P16: =$X$17/29 -> 0 | Q16: =$X$16/29 -> 0 | R16: =$X$20/29 -> 0 | S16: =$X$15/29 -> 0 | U16: =C16+B16+K16+L16+M16+O16+P16+Q16+R16+S16+T16+D16+E16+F16+G16+I16+H16 -> 0 | W16: Contabilidade | Y16: =X16 -> 0
A17: 12 | O17: =$X$18/29 -> 0 | P17: =$X$17/29 -> 0 | Q17: =$X$16/29 -> 0 | R17: =$X$20/29 -> 0 | S17: =$X$15/29 -> 0 | U17: =C17+B17+K17+L17+M17+O17+P17+Q17+R17+S17+T17+D17+E17+F17+G17+I17+H17 -> 0 | W17: Empréstimo | Y17: =X17 -> 0
A18: 13 | O18: =$X$18/29 -> 0 | P18: =$X$17/29 -> 0 | Q18: =$X$16/29 -> 0 | R18: =$X$20/29 -> 0 | S18: =$X$15/29 -> 0 | U18: =C18+B18+K18+L18+M18+O18+P18+Q18+R18+S18+T18+D18+E18+F18+G18+I18+H18 -> 0 | W18: Pró Labore | Y18: =X18 -> 0
A19: 14 | O19: =$X$18/29 -> 0 | P19: =$X$17/29 -> 0 | Q19: =$X$16/29 -> 0 | R19: =$X$20/29 -> 0 | S19: =$X$15/29 -> 0 | U19: =C19+B19+K19+L19+M19+O19+P19+Q19+R19+S19+T19+D19+E19+F19+G19+I19+H19 -> 0 | W19: Previdência Privada | X19: =(X18-X21)*14% -> 0 | Y19: =(Y18-Y21)*14% -> 0
A20: 15 | O20: =$X$18/29 -> 0 | P20: =$X$17/29 -> 0 | Q20: =$X$16/29 -> 0 | R20: =$X$20/29 -> 0 | S20: =$X$15/29 -> 0 | U20: =C20+B20+K20+L20+M20+O20+P20+Q20+R20+S20+T20+D20+E20+F20+G20+I20+H20 -> 0 | W20: ERP Mensal | Y20: =X20 -> 0
A21: 16 | O21: =$X$18/29 -> 0 | P21: =$X$17/29 -> 0 | Q21: =$X$16/29 -> 0 | R21: =$X$20/29 -> 0 | S21: =$X$15/29 -> 0 | U21: =C21+B21+K21+L21+M21+O21+P21+Q21+R21+S21+T21+D21+E21+F21+G21+I21+H21 -> 0 | W21: Lucro Bruto | X21: =X3+X5+X6+X9+X10+X12+X13+X15+X16+X17+X18+X20+X7 -> 0 | Y21: =Y3+Y5+Y6+Y7+Y9+Y10+Y12+Y13+Y15+Y16+Y17+Y18+Y20 -> 0
A22: 17 | O22: =$X$18/29 -> 0 | P22: =$X$17/29 -> 0 | Q22: =$X$16/29 -> 0 | R22: =$X$20/29 -> 0 | S22: =$X$15/29 -> 0 | U22: =C22+B22+K22+L22+M22+O22+P22+Q22+R22+S22+T22+D22+E22+F22+G22+I22+H22 -> 0 | W22: Lucro Liquido | X22: =X3+X5+X6+X7+X9+X10+X12+X13+X14+X15+X16+X17+X18+X19+X20 -> 0 | Y22: =Y3+Y5+Y6+Y7+Y9+Y10+Y12+Y13+Y15+Y16+Y17+Y18+Y19+Y20 -> 0
A23: 18 | O23: =$X$18/29 -> 0 | P23: =$X$17/29 -> 0 | Q23: =$X$16/29 -> 0 | R23: =$X$20/29 -> 0 | S23: =$X$15/29 -> 0 | U23: =C23+B23+K23+L23+M23+O23+P23+Q23+R23+S23+T23+D23+E23+F23+G23+I23+H23 -> 0
A24: 19 | O24: =$X$18/29 -> 0 | P24: =$X$17/29 -> 0 | Q24: =$X$16/29 -> 0 | R24: =$X$20/29 -> 0 | S24: =$X$15/29 -> 0 | U24: =C24+B24+K24+L24+M24+O24+P24+Q24+R24+S24+T24+D24+E24+F24+G24+I24+H24 -> 0 | W24: Fatura Mercado Livre | X24: =X6+X5+X14+X13 -> 0 | Y24: =Y6+Y5+Y14+Y13 -> 0
A25: 20 | O25: =$X$18/29 -> 0 | P25: =$X$17/29 -> 0 | Q25: =$X$16/29 -> 0 | R25: =$X$20/29 -> 0 | S25: =$X$15/29 -> 0 | U25: =C25+B25+K25+L25+M25+O25+P25+Q25+R25+S25+T25+D25+E25+F25+G25+I25+H25 -> 0
A26: 21 | O26: =$X$18/29 -> 0 | P26: =$X$17/29 -> 0 | Q26: =$X$16/29 -> 0 | R26: =$X$20/29 -> 0 | S26: =$X$15/29 -> 0 | U26: =C26+B26+K26+L26+M26+O26+P26+Q26+R26+S26+T26+D26+E26+F26+G26+I26+H26 -> 0
A27: 22 | O27: =$X$18/29 -> 0 | P27: =$X$17/29 -> 0 | Q27: =$X$16/29 -> 0 | R27: =$X$20/29 -> 0 | S27: =$X$15/29 -> 0 | U27: =C27+B27+K27+L27+M27+O27+P27+Q27+R27+S27+T27+D27+E27+F27+G27+I27+H27 -> 0 | W27: DLR - Sócio | X27: =(X22*X30) -> 0 | Y27: =Y22*50% -> 0
A28: 23 | O28: =$X$18/29 -> 0 | P28: =$X$17/29 -> 0 | Q28: =$X$16/29 -> 0 | R28: =$X$20/29 -> 0 | S28: =$X$15/29 -> 0 | U28: =C28+B28+K28+L28+M28+O28+P28+Q28+R28+S28+T28+D28+E28+F28+G28+I28+H28 -> 0 | W28: Reinvestimento - Empresa | X28: =X22*X31 -> 0 | Y28: =Y22*X31 -> 0
A29: 24 | O29: =$X$18/29 -> 0 | P29: =$X$17/29 -> 0 | Q29: =$X$16/29 -> 0 | R29: =$X$20/29 -> 0 | S29: =$X$15/29 -> 0 | U29: =C29+B29+K29+L29+M29+O29+P29+Q29+R29+S29+T29+D29+E29+F29+G29+I29+H29 -> 0
A30: 25 | O30: =$X$18/29 -> 0 | P30: =$X$17/29 -> 0 | Q30: =$X$16/29 -> 0 | R30: =$X$20/29 -> 0 | S30: =$X$15/29 -> 0 | U30: =C30+B30+K30+L30+M30+O30+P30+Q30+R30+S30+T30+D30+E30+F30+G30+I30+H30 -> 0 | W30: % DLR do Sócio | X30: 0.5
A31: 26 | O31: =$X$18/29 -> 0 | P31: =$X$17/29 -> 0 | Q31: =$X$16/29 -> 0 | R31: =$X$20/29 -> 0 | S31: =$X$15/29 -> 0 | U31: =C31+B31+K31+L31+M31+O31+P31+Q31+R31+S31+T31+D31+E31+F31+G31+I31+H31 -> 0 | W31: Reinvestimento - Empresa | X31: 0.5
A32: 27 | O32: =$X$18/29 -> 0 | P32: =$X$17/29 -> 0 | Q32: =$X$16/29 -> 0 | R32: =$X$20/29 -> 0 | S32: =$X$15/29 -> 0 | U32: =C32+B32+K32+L32+M32+O32+P32+Q32+R32+S32+T32+D32+E32+F32+G32+I32+H32 -> 0
A33: 28 | O33: =$X$18/29 -> 0 | P33: =$X$17/29 -> 0 | Q33: =$X$16/29 -> 0 | R33: =$X$20/29 -> 0 | S33: =$X$15/29 -> 0 | U33: =C33+B33+K33+L33+M33+O33+P33+Q33+R33+S33+T33+D33+E33+F33+G33+I33+H33 -> 0 | Y33: Células que estão com formulas e não devem ser alteradas
Y34: Células que devem ser imputados os valores manualmente
A35: Total | C35: =SUM(C4:C33) -> 0 | D35: =SUM(D4:D33) -> 0 | E35: =SUM(E4:E33) -> 0 | F35: =SUM(F4:F33) -> 0 | G35: =SUM(G4:G33) -> 0 | H35: =SUM(H4:H33) -> 0 | I35: =SUM(I4:I33) -> 0

Sheet Março 2026
A1: Controle Mensal - Março 2026
X2: Previsto | Y2: Real
A3: Dia | B3: Armazenagem | C3: Mercado Livre | D3: Magalu | E3: Casas Bahia | F3: Amazon | G3: Shopee | H3: TikTok | I3: Presencial | J3: Ticket Médio | K3: Ads | L3: Custo | M3: Tarifa | N3: Frete | O3: Salário | P3: Empréstimo | Q3: Contabilidade | R3: ERP | S3: INSS | T3: Outras Taxas | U3: Lucro Real do dia | W3: Faturamento | X3: =SUM(C36:I36) -> 0 | AA3: ROAS Atual | AB3: Objetivo
A4: 30 | U4: =C4+B4+K4+L4+M4+O4+P4+Q4+R4+S4+T4+D4+E4+F4+G4+I4+H4+N4 -> 0 | W4: Aliquota de Imposto | X4: 0.04 | AA4: =IFERROR(-(X3/(X6+X7)),"") | AB4: =IF($AA$4 > 12, "⭐ Excelente", IF($AA$4 >= 6, "✅ Saudável", IF($AA$4 < 5, "🛑 Perigo", "⚠️ Atenção"))) -> ⭐ Excelente
A5: 31 | U5: =C5+B5+K5+L5+M5+O5+P5+Q5+R5+S5+T5+D5+E5+F5+G5+I5+H5+N5 -> 0 | W5: Total Gasto em armazenagem | X5: =SUM(B4:B33) -> 0
A6: 1 | O6: =$X$18/29 -> 0 | P6: =$X$17/29 -> 0 | Q6: =$X$16/29 -> 0 | R6: =$X$19/29 -> 0 | S6: =$X$15/29 -> 0 | U6: =C6+B6+K6+L6+M6+O6+P6+Q6+R6+S6+T6+D6+E6+F6+G6+I6+H6+N6 -> 0 | W6: Ads Mercado Livre | X6: =SUM(K4:K33) -> 0 | AA6: Break-Even Point | AB6: =IFERROR(ABS(SUM(X14:X19)) / ((X3 - ABS(SUM(X5:X12))) / X3), "")
A7: 2 | O7: =$X$18/29 -> 0 | P7: =$X$17/29 -> 0 | Q7: =$X$16/29 -> 0 | R7: =$X$19/29 -> 0 | S7: =$X$15/29 -> 0 | U7: =C7+B7+K7+L7+M7+O7+P7+Q7+R7+S7+T7+D7+E7+F7+G7+I7+H7+N7 -> 0 | W7: Ads Outras Plataformas avulsas
A8: 3 | O8: =$X$18/29 -> 0 | P8: =$X$17/29 -> 0 | Q8: =$X$16/29 -> 0 | R8: =$X$19/29 -> 0 | S8: =$X$15/29 -> 0 | U8: =C8+B8+K8+L8+M8+O8+P8+Q8+R8+S8+T8+D8+E8+F8+G8+I8+H8+N8 -> 0 | W8: ticket médio mensal | X8: =(SUM(J4:J33))/31 -> 0
A9: 4 | O9: =$X$18/29 -> 0 | P9: =$X$17/29 -> 0 | Q9: =$X$16/29 -> 0 | R9: =$X$19/29 -> 0 | S9: =$X$15/29 -> 0 | U9: =C9+B9+K9+L9+M9+O9+P9+Q9+R9+S9+T9+D9+E9+F9+G9+I9+H9+N9 -> 0 | W9: Custo com Produtos | X9: =SUM(L4:L33) -> 0
A10: 5 | O10: =$X$18/29 -> 0 | P10: =$X$17/29 -> 0 | Q10: =$X$16/29 -> 0 | R10: =$X$19/29 -> 0 | S10: =$X$15/29 -> 0 | U10: =C10+B10+K10+L10+M10+O10+P10+Q10+R10+S10+T10+D10+E10+F10+G10+I10+H10+N10 -> 0 | W10: Tarifas Marketplaces | X10: =SUM(M4:M33) -> 0
A11: 6 | O11: =$X$18/29 -> 0 | P11: =$X$17/29 -> 0 | Q11: =$X$16/29 -> 0 | R11: =$X$19/29 -> 0 | S11: =$X$15/29 -> 0 | U11: =C11+B11+K11+L11+M11+O11+P11+Q11+R11+S11+T11+D11+E11+F11+G11+I11+H11+N11 -> 0 | W11: Frete | X11: =SUM(N4:N34) -> 0
A12: 7 | O12: =$X$18/29 -> 0 | P12: =$X$17/29 -> 0 | Q12: =$X$16/29 -> 0 | R12: =$X$19/29 -> 0 | S12: =$X$15/29 -> 0 | U12: =C12+B12+K12+L12+M12+O12+P12+Q12+R12+S12+T12+D12+E12+F12+G12+I12+H12+N12 -> 0 | W12: Imposto - DAS | X12: =-X3*X4 -> 0
A13: 8 | O13: =$X$18/29 -> 0 | P13: =$X$17/29 -> 0 | Q13: =$X$16/29 -> 0 | R13: =$X$19/29 -> 0 | S13: =$X$15/29 -> 0 | U13: =C13+B13+K13+L13+M13+O13+P13+Q13+R13+S13+T13+D13+E13+F13+G13+I13+H13+N13 -> 0 | W13: Página Oficial Mercado Livre
A14: 9 | O14: =$X$18/29 -> 0 | P14: =$X$17/29 -> 0 | Q14: =$X$16/29 -> 0 | R14: =$X$19/29 -> 0 | S14: =$X$15/29 -> 0 | U14: =C14+B14+K14+L14+M14+O14+P14+Q14+R14+S14+T14+D14+E14+F14+G14+I14+H14+N14 -> 0 | W14: Outras Taxas | X14: =SUM(T4:T33) -> 0
A15: 10 | O15: =$X$18/29 -> 0 | P15: =$X$17/29 -> 0 | Q15: =$X$16/29 -> 0 | R15: =$X$19/29 -> 0 | S15: =$X$15/29 -> 0 | U15: =C15+B15+K15+L15+M15+O15+P15+Q15+R15+S15+T15+D15+E15+F15+G15+I15+H15+N15 -> 0 | W15: INSS
A16: 11 | O16: =$X$18/29 -> 0 | P16: =$X$17/29 -> 0 | Q16: =$X$16/29 -> 0 | R16: =$X$19/29 -> 0 | S16: =$X$15/29 -> 0 | U16: =C16+B16+K16+L16+M16+O16+P16+Q16+R16+S16+T16+D16+E16+F16+G16+I16+H16+N16 -> 0 | W16: Contabilidade
A17: 12 | O17: =$X$18/29 -> 0 | P17: =$X$17/29 -> 0 | Q17: =$X$16/29 -> 0 | R17: =$X$19/29 -> 0 | S17: =$X$15/29 -> 0 | U17: =C17+B17+K17+L17+M17+O17+P17+Q17+R17+S17+T17+D17+E17+F17+G17+I17+H17+N17 -> 0 | W17: Empréstimo
A18: 13 | O18: =$X$18/29 -> 0 | P18: =$X$17/29 -> 0 | Q18: =$X$16/29 -> 0 | R18: =$X$19/29 -> 0 | S18: =$X$15/29 -> 0 | U18: =C18+B18+K18+L18+M18+O18+P18+Q18+R18+S18+T18+D18+E18+F18+G18+I18+H18+N18 -> 0 | W18: Pró Labore
A19: 14 | O19: =$X$18/29 -> 0 | P19: =$X$17/29 -> 0 | Q19: =$X$16/29 -> 0 | R19: =$X$19/29 -> 0 | S19: =$X$15/29 -> 0 | U19: =C19+B19+K19+L19+M19+O19+P19+Q19+R19+S19+T19+D19+E19+F19+G19+I19+H19+N19 -> 0 | W19: Previdência Privada | X19: =(X18-X21)*14% -> 0
A20: 15 | O20: =$X$18/29 -> 0 | P20: =$X$17/29 -> 0 | Q20: =$X$16/29 -> 0 | R20: =$X$19/29 -> 0 | S20: =$X$15/29 -> 0 | U20: =C20+B20+K20+L20+M20+O20+P20+Q20+R20+S20+T20+D20+E20+F20+G20+I20+H20+N20 -> 0 | W20: ERP Mensal
A21: 16 | O21: =$X$18/29 -> 0 | P21: =$X$17/29 -> 0 | Q21: =$X$16/29 -> 0 | R21: =$X$19/29 -> 0 | S21: =$X$15/29 -> 0 | U21: =C21+B21+K21+L21+M21+O21+P21+Q21+R21+S21+T21+D21+E21+F21+G21+I21+H21+N21 -> 0 | W21: Lucro Bruto | X21: =X3+X5+X6+X9+X10+X12+X13+X15+X16+X17+X18+X20+X7+X11 -> 0 | Y21: =Y3+Y5+Y6+Y7+Y9+Y10+Y12+Y13+Y15+Y16+Y17+Y18+Y20 -> 0
A22: 17 | O22: =$X$18/29 -> 0 | P22: =$X$17/29 -> 0 | Q22: =$X$16/29 -> 0 | R22: =$X$19/29 -> 0 | S22: =$X$15/29 -> 0 | U22: =C22+B22+K22+L22+M22+O22+P22+Q22+R22+S22+T22+D22+E22+F22+G22+I22+H22+N22 -> 0 | W22: Lucro Liquido | X22: =X3+X5+X6+X7+X9+X10+X12+X13+X14+X15+X16+X17+X18+X19+X20+X11 -> 0 | Y22: =Y3+Y5+Y6+Y7+Y9+Y10+Y12+Y13+Y15+Y16+Y17+Y18+Y19+Y20 -> 0
A23: 18 | O23: =$X$18/29 -> 0 | P23: =$X$17/29 -> 0 | Q23: =$X$16/29 -> 0 | R23: =$X$19/29 -> 0 | S23: =$X$15/29 -> 0 | U23: =C23+B23+K23+L23+M23+O23+P23+Q23+R23+S23+T23+D23+E23+F23+G23+I23+H23+N23 -> 0
A24: 19 | O24: =$X$18/29 -> 0 | P24: =$X$17/29 -> 0 | Q24: =$X$16/29 -> 0 | R24: =$X$19/29 -> 0 | S24: =$X$15/29 -> 0 | U24: =C24+B24+K24+L24+M24+O24+P24+Q24+R24+S24+T24+D24+E24+F24+G24+I24+H24+N24 -> 0 | W24: Fatura Mercado Livre | X24: =X6+X5+X14+X13 -> 0
A25: 20 | O25: =$X$18/29 -> 0 | P25: =$X$17/29 -> 0 | Q25: =$X$16/29 -> 0 | R25: =$X$19/29 -> 0 | S25: =$X$15/29 -> 0 | U25: =C25+B25+K25+L25+M25+O25+P25+Q25+R25+S25+T25+D25+E25+F25+G25+I25+H25+N25 -> 0
A26: 21 | O26: =$X$18/29 -> 0 | P26: =$X$17/29 -> 0 | Q26: =$X$16/29 -> 0 | R26: =$X$19/29 -> 0 | S26: =$X$15/29 -> 0 | U26: =C26+B26+K26+L26+M26+O26+P26+Q26+R26+S26+T26+D26+E26+F26+G26+I26+H26+N26 -> 0
A27: 22 | O27: =$X$18/29 -> 0 | P27: =$X$17/29 -> 0 | Q27: =$X$16/29 -> 0 | R27: =$X$19/29 -> 0 | S27: =$X$15/29 -> 0 | U27: =C27+B27+K27+L27+M27+O27+P27+Q27+R27+S27+T27+D27+E27+F27+G27+I27+H27+N27 -> 0 | W27: DLR - Sócio | X27: =(X22*X30) -> 0 | Y27: =Y22*50% -> 0
A28: 23 | O28: =$X$18/29 -> 0 | P28: =$X$17/29 -> 0 | Q28: =$X$16/29 -> 0 | R28: =$X$19/29 -> 0 | S28: =$X$15/29 -> 0 | U28: =C28+B28+K28+L28+M28+O28+P28+Q28+R28+S28+T28+D28+E28+F28+G28+I28+H28+N28 -> 0 | W28: Reinvestimento - Empresa | X28: =X22*X31 -> 0 | Y28: =Y22*X31 -> 0
A29: 24 | O29: =$X$18/29 -> 0 | P29: =$X$17/29 -> 0 | Q29: =$X$16/29 -> 0 | R29: =$X$19/29 -> 0 | S29: =$X$15/29 -> 0 | U29: =C29+B29+K29+L29+M29+O29+P29+Q29+R29+S29+T29+D29+E29+F29+G29+I29+H29+N29 -> 0
A30: 25 | O30: =$X$18/29 -> 0 | P30: =$X$17/29 -> 0 | Q30: =$X$16/29 -> 0 | R30: =$X$19/29 -> 0 | S30: =$X$15/29 -> 0 | U30: =C30+B30+K30+L30+M30+O30+P30+Q30+R30+S30+T30+D30+E30+F30+G30+I30+H30+N30 -> 0 | W30: % DLR do Sócio | X30: 0.5
A31: 26 | O31: =$X$18/29 -> 0 | P31: =$X$17/29 -> 0 | Q31: =$X$16/29 -> 0 | R31: =$X$19/29 -> 0 | S31: =$X$15/29 -> 0 | U31: =C31+B31+K31+L31+M31+O31+P31+Q31+R31+S31+T31+D31+E31+F31+G31+I31+H31+N31 -> 0 | W31: Reinvestimento - Empresa | X31: 0.5
A32: 27 | O32: =$X$18/29 -> 0 | P32: =$X$17/29 -> 0 | Q32: =$X$16/29 -> 0 | R32: =$X$19/29 -> 0 | S32: =$X$15/29 -> 0 | U32: =C32+B32+K32+L32+M32+O32+P32+Q32+R32+S32+T32+D32+E32+F32+G32+I32+H32+N32 -> 0 | Y32: Células que estão com formulas e não devem ser alteradas
A33: 28 | O33: =$X$18/29 -> 0 | P33: =$X$17/29 -> 0 | Q33: =$X$16/29 -> 0 | R33: =$X$19/29 -> 0 | S33: =$X$15/29 -> 0 | U33: =C33+B33+K33+L33+M33+O33+P33+Q33+R33+S33+T33+D33+E33+F33+G33+I33+H33+N33 -> 0 | Y33: Células que devem ser imputados os valores manualmente
A34: 29 | O34: =$X$18/29 -> 0 | P34: =$X$17/29 -> 0 | Q34: =$X$16/29 -> 0 | R34: =$X$19/29 -> 0 | S34: =$X$15/29 -> 0 | U34: =C34+B34+K34+L34+M34+O34+P34+Q34+R34+S34+T34+D34+E34+F34+G34+I34+H34+N34 -> 0
A36: Total | C36: =SUM(C4:C34) -> 0 | D36: =SUM(D4:D34) -> 0 | E36: =SUM(E4:E34) -> 0 | F36: =SUM(F4:F34) -> 0 | G36: =SUM(G4:G34) -> 0 | H36: =SUM(H4:H34) -> 0 | I36: =SUM(I4:I34) -> 0

Sheet Abril 2026
A1: Controle Mensal - Abril 2026
X2: Previsto | Y2: Real
A3: Dia | B3: Armazenagem | C3: Mercado Livre | D3: Magalu | E3: Casas Bahia | F3: Amazon | G3: Shopee | H3: TikTok | I3: Presencial | J3: Ticket Médio | K3: Ads | L3: Custo | M3: Tarifa | N3: Frete | O3: Salário | P3: Empréstimo | Q3: Contabilidade | R3: ERP | S3: INSS | T3: Outras Taxas | U3: Lucro Real do dia | W3: Faturamento | X3: =SUM(C35:I35) -> 0 | AA3: ROAS Atual | AB3: Objetivo
A4: 30 | O4: =$X$18/30 -> 0 | P4: =$X$17/30 -> 0 | Q4: =$X$16/30 -> 0 | R4: =$X$19/30 -> 0 | S4: =$X$15/30 -> 0 | U4: =C4+B4+K4+L4+M4+O4+P4+Q4+R4+S4+T4+D4+E4+F4+G4+I4+H4 -> 0 | W4: Aliquota de Imposto | X4: 0.04 | AA4: =IFERROR(-(X3/(X6+X7)),"") | AB4: =IF($AA$4 > 12, "⭐ Excelente", IF($AA$4 >= 6, "✅ Saudável", IF($AA$4 < 5, "🛑 Perigo", "⚠️ Atenção"))) -> ⭐ Excelente
A5: 31 | O5: =$X$18/30 -> 0 | P5: =$X$17/30 -> 0 | Q5: =$X$16/30 -> 0 | R5: =$X$19/30 -> 0 | S5: =$X$15/30 -> 0 | U5: =C5+B5+K5+L5+M5+O5+P5+Q5+R5+S5+T5+D5+E5+F5+G5+I5+H5 -> 0 | W5: Total Gasto em armazenagem | X5: =SUM(B4:B33) -> 0
A6: 1 | O6: =$X$18/30 -> 0 | P6: =$X$17/30 -> 0 | Q6: =$X$16/30 -> 0 | R6: =$X$19/30 -> 0 | S6: =$X$15/30 -> 0 | U6: =C6+B6+K6+L6+M6+O6+P6+Q6+R6+S6+T6+D6+E6+F6+G6+I6+H6 -> 0 | W6: Ads Mercado Livre | X6: =SUM(K4:K33) -> 0 | AA6: Break-Even Point | AB6: =IFERROR(ABS(SUM(X14:X19)) / ((X3 - ABS(SUM(X5:X12))) / X3), "")
A7: 2 | O7: =$X$18/30 -> 0 | P7: =$X$17/30 -> 0 | Q7: =$X$16/30 -> 0 | R7: =$X$19/30 -> 0 | S7: =$X$15/30 -> 0 | U7: =C7+B7+K7+L7+M7+O7+P7+Q7+R7+S7+T7+D7+E7+F7+G7+I7+H7 -> 0 | W7: Ads Outras Plataformas avulsas
A8: 3 | O8: =$X$18/30 -> 0 | P8: =$X$17/30 -> 0 | Q8: =$X$16/30 -> 0 | R8: =$X$19/30 -> 0 | S8: =$X$15/30 -> 0 | U8: =C8+B8+K8+L8+M8+O8+P8+Q8+R8+S8+T8+D8+E8+F8+G8+I8+H8 -> 0 | W8: ticket médio mensal | X8: =(SUM(J4:J33))/31 -> 0
A9: 4 | O9: =$X$18/30 -> 0 | P9: =$X$17/30 -> 0 | Q9: =$X$16/30 -> 0 | R9: =$X$19/30 -> 0 | S9: =$X$15/30 -> 0 | U9: =C9+B9+K9+L9+M9+O9+P9+Q9+R9+S9+T9+D9+E9+F9+G9+I9+H9 -> 0 | W9: Custo com Produtos | X9: =SUM(L4:L33) -> 0
A10: 5 | O10: =$X$18/30 -> 0 | P10: =$X$17/30 -> 0 | Q10: =$X$16/30 -> 0 | R10: =$X$19/30 -> 0 | S10: =$X$15/30 -> 0 | U10: =C10+B10+K10+L10+M10+O10+P10+Q10+R10+S10+T10+D10+E10+F10+G10+I10+H10 -> 0 | W10: Tarifas Marketplaces | X10: =SUM(M4:M33) -> 0
A11: 6 | O11: =$X$18/30 -> 0 | P11: =$X$17/30 -> 0 | Q11: =$X$16/30 -> 0 | R11: =$X$19/30 -> 0 | S11: =$X$15/30 -> 0 | U11: =C11+B11+K11+L11+M11+O11+P11+Q11+R11+S11+T11+D11+E11+F11+G11+I11+H11 -> 0 | W11: Frete | X11: =SUM(N4:N34) -> 0
A12: 7 | O12: =$X$18/30 -> 0 | P12: =$X$17/30 -> 0 | Q12: =$X$16/30 -> 0 | R12: =$X$19/30 -> 0 | S12: =$X$15/30 -> 0 | U12: =C12+B12+K12+L12+M12+O12+P12+Q12+R12+S12+T12+D12+E12+F12+G12+I12+H12 -> 0 | W12: Imposto - DAS | X12: =-X3*X4 -> 0
A13: 8 | O13: =$X$18/30 -> 0 | P13: =$X$17/30 -> 0 | Q13: =$X$16/30 -> 0 | R13: =$X$19/30 -> 0 | S13: =$X$15/30 -> 0 | U13: =C13+B13+K13+L13+M13+O13+P13+Q13+R13+S13+T13+D13+E13+F13+G13+I13+H13 -> 0 | W13: Página Oficial Mercado Livre
A14: 9 | O14: =$X$18/30 -> 0 | P14: =$X$17/30 -> 0 | Q14: =$X$16/30 -> 0 | R14: =$X$19/30 -> 0 | S14: =$X$15/30 -> 0 | U14: =C14+B14+K14+L14+M14+O14+P14+Q14+R14+S14+T14+D14+E14+F14+G14+I14+H14 -> 0 | W14: Outras Taxas | X14: =SUM(T4:T33) -> 0
A15: 10 | O15: =$X$18/30 -> 0 | P15: =$X$17/30 -> 0 | Q15: =$X$16/30 -> 0 | R15: =$X$19/30 -> 0 | S15: =$X$15/30 -> 0 | U15: =C15+B15+K15+L15+M15+O15+P15+Q15+R15+S15+T15+D15+E15+F15+G15+I15+H15 -> 0 | W15: INSS
A16: 11 | O16: =$X$18/30 -> 0 | P16: =$X$17/30 -> 0 | Q16: =$X$16/30 -> 0 | R16: =$X$19/30 -> 0 | S16: =$X$15/30 -> 0 | U16: =C16+B16+K16+L16+M16+O16+P16+Q16+R16+S16+T16+D16+E16+F16+G16+I16+H16 -> 0 | W16: Contabilidade
A17: 12 | O17: =$X$18/30 -> 0 | P17: =$X$17/30 -> 0 | Q17: =$X$16/30 -> 0 | R17: =$X$19/30 -> 0 | S17: =$X$15/30 -> 0 | U17: =C17+B17+K17+L17+M17+O17+P17+Q17+R17+S17+T17+D17+E17+F17+G17+I17+H17 -> 0 | W17: Empréstimo | X17: 0
A18: 13 | O18: =$X$18/30 -> 0 | P18: =$X$17/30 -> 0 | Q18: =$X$16/30 -> 0 | R18: =$X$19/30 -> 0 | S18: =$X$15/30 -> 0 | U18: =C18+B18+K18+L18+M18+O18+P18+Q18+R18+S18+T18+D18+E18+F18+G18+I18+H18 -> 0 | W18: Pró Labore
A19: 14 | O19: =$X$18/30 -> 0 | P19: =$X$17/30 -> 0 | Q19: =$X$16/30 -> 0 | R19: =$X$19/30 -> 0 | S19: =$X$15/30 -> 0 | U19: =C19+B19+K19+L19+M19+O19+P19+Q19+R19+S19+T19+D19+E19+F19+G19+I19+H19 -> 0 | W19: Previdência Privada | X19: =(X18*20%)+(-X21*11%) -> 0
A20: 15 | O20: =$X$18/30 -> 0 | P20: =$X$17/30 -> 0 | Q20: =$X$16/30 -> 0 | R20: =$X$19/30 -> 0 | S20: =$X$15/30 -> 0 | U20: =C20+B20+K20+L20+M20+O20+P20+Q20+R20+S20+T20+D20+E20+F20+G20+I20+H20 -> 0 | W20: ERP Mensal
A21: 16 | O21: =$X$18/30 -> 0 | P21: =$X$17/30 -> 0 | Q21: =$X$16/30 -> 0 | R21: =$X$19/30 -> 0 | S21: =$X$15/30 -> 0 | U21: =C21+B21+K21+L21+M21+O21+P21+Q21+R21+S21+T21+D21+E21+F21+G21+I21+H21 -> 0 | W21: Lucro Bruto | X21: =X3+X5+X6+X9+X10+X12+X13+X15+X16+X17+X18+X20+X7 -> 0 | Y21: =Y3+Y5+Y6+Y7+Y9+Y10+Y12+Y13+Y15+Y16+Y17+Y18+Y20 -> 0
A22: 17 | O22: =$X$18/30 -> 0 | P22: =$X$17/30 -> 0 | Q22: =$X$16/30 -> 0 | R22: =$X$19/30 -> 0 | S22: =$X$15/30 -> 0 | U22: =C22+B22+K22+L22+M22+O22+P22+Q22+R22+S22+T22+D22+E22+F22+G22+I22+H22 -> 0 | W22: Lucro Liquido | X22: =X3+X5+X6+X7+X9+X10+X12+X13+X14+X15+X16+X17+X18+X19+X20 -> 0 | Y22: =Y3+Y5+Y6+Y7+Y9+Y10+Y12+Y13+Y15+Y16+Y17+Y18+Y19+Y20 -> 0
A23: 18 | O23: =$X$18/30 -> 0 | P23: =$X$17/30 -> 0 | Q23: =$X$16/30 -> 0 | R23: =$X$19/30 -> 0 | S23: =$X$15/30 -> 0 | U23: =C23+B23+K23+L23+M23+O23+P23+Q23+R23+S23+T23+D23+E23+F23+G23+I23+H23 -> 0
A24: 19 | O24: =$X$18/30 -> 0 | P24: =$X$17/30 -> 0 | Q24: =$X$16/30 -> 0 | R24: =$X$19/30 -> 0 | S24: =$X$15/30 -> 0 | U24: =C24+B24+K24+L24+M24+O24+P24+Q24+R24+S24+T24+D24+E24+F24+G24+I24+H24 -> 0 | W24: Fatura Mercado Livre | X24: =X6+X5+X14+X13 -> 0
A25: 20 | O25: =$X$18/30 -> 0 | P25: =$X$17/30 -> 0 | Q25: =$X$16/30 -> 0 | R25: =$X$19/30 -> 0 | S25: =$X$15/30 -> 0 | U25: =C25+B25+K25+L25+M25+O25+P25+Q25+R25+S25+T25+D25+E25+F25+G25+I25+H25 -> 0
A26: 21 | O26: =$X$18/30 -> 0 | P26: =$X$17/30 -> 0 | Q26: =$X$16/30 -> 0 | R26: =$X$19/30 -> 0 | S26: =$X$15/30 -> 0 | U26: =C26+B26+K26+L26+M26+O26+P26+Q26+R26+S26+T26+D26+E26+F26+G26+I26+H26 -> 0
A27: 22 | O27: =$X$18/30 -> 0 | P27: =$X$17/30 -> 0 | Q27: =$X$16/30 -> 0 | R27: =$X$19/30 -> 0 | S27: =$X$15/30 -> 0 | U27: =C27+B27+K27+L27+M27+O27+P27+Q27+R27+S27+T27+D27+E27+F27+G27+I27+H27 -> 0 | W27: DLR - Sócio | X27: =(X22*X30) -> 0 | Y27: =Y22*50% -> 0
A28: 23 | O28: =$X$18/30 -> 0 | P28: =$X$17/30 -> 0 | Q28: =$X$16/30 -> 0 | R28: =$X$19/30 -> 0 | S28: =$X$15/30 -> 0 | U28: =C28+B28+K28+L28+M28+O28+P28+Q28+R28+S28+T28+D28+E28+F28+G28+I28+H28 -> 0 | W28: Reinvestimento - Empresa | X28: =X22*X31 -> 0 | Y28: =Y22*X31 -> 0
A29: 24 | O29: =$X$18/30 -> 0 | P29: =$X$17/30 -> 0 | Q29: =$X$16/30 -> 0 | R29: =$X$19/30 -> 0 | S29: =$X$15/30 -> 0 | U29: =C29+B29+K29+L29+M29+O29+P29+Q29+R29+S29+T29+D29+E29+F29+G29+I29+H29 -> 0
A30: 25 | O30: =$X$18/30 -> 0 | P30: =$X$17/30 -> 0 | Q30: =$X$16/30 -> 0 | R30: =$X$19/30 -> 0 | S30: =$X$15/30 -> 0 | U30: =C30+B30+K30+L30+M30+O30+P30+Q30+R30+S30+T30+D30+E30+F30+G30+I30+H30 -> 0 | W30: % DLR do Sócio | X30: 0.5
A31: 26 | O31: =$X$18/30 -> 0 | P31: =$X$17/30 -> 0 | Q31: =$X$16/30 -> 0 | R31: =$X$19/30 -> 0 | S31: =$X$15/30 -> 0 | U31: =C31+B31+K31+L31+M31+O31+P31+Q31+R31+S31+T31+D31+E31+F31+G31+I31+H31 -> 0 | W31: Reinvestimento - Empresa | X31: 0.5
A32: 27 | O32: =$X$18/30 -> 0 | P32: =$X$17/30 -> 0 | Q32: =$X$16/30 -> 0 | R32: =$X$19/30 -> 0 | S32: =$X$15/30 -> 0 | U32: =C32+B32+K32+L32+M32+O32+P32+Q32+R32+S32+T32+D32+E32+F32+G32+I32+H32 -> 0 | Y32: Células que estão com formulas e não devem ser alteradas
A33: 28 | O33: =$X$18/30 -> 0 | P33: =$X$17/30 -> 0 | Q33: =$X$16/30 -> 0 | R33: =$X$19/30 -> 0 | S33: =$X$15/30 -> 0 | U33: =C33+B33+K33+L33+M33+O33+P33+Q33+R33+S33+T33+D33+E33+F33+G33+I33+H33 -> 0 | Y33: Células que devem ser imputados os valores manualmente
A34: 29 | O34: =$X$18/30 -> 0 | P34: =$X$17/30 -> 0 | Q34: =$X$16/30 -> 0 | R34: =$X$19/30 -> 0 | S34: =$X$15/30 -> 0 | U34: =C34+B34+K34+L34+M34+O34+P34+Q34+R34+S34+T34+D34+E34+F34+G34+I34+H34 -> 0
A36: Total | C36: =SUM(C4:C34) -> 0 | D36: =SUM(D4:D34) -> 0 | E36: =SUM(E4:E34) -> 0 | F36: =SUM(F4:F34) -> 0 | G36: =SUM(G4:G34) -> 0 | H36: =SUM(H4:H34) -> 0 | I36: =SUM(I4:I34) -> 0

Sheet Maio 2026
A1: Controle Mensal - Maio 2026
X2: Previsto | Y2: Real
A3: Dia | B3: Armazenagem | C3: Mercado Livre | D3: Magalu | E3: Casas Bahia | F3: Amazon | G3: Shopee | H3: TikTok | I3: Presencial | J3: Ticket Médio | K3: Ads | L3: Custo | M3: Tarifa | N3: Frete | O3: Salário | P3: Empréstimo | Q3: Contabilidade | R3: ERP | S3: INSS | T3: Outras Taxas | U3: Lucro Real do dia | W3: Faturamento | X3: =SUM(C35:I35) -> 0 | AA3: ROAS Atual | AB3: Objetivo
A4: 30 | O4: =$X$18/30 -> 0 | P4: =$X$17/30 -> 0 | Q4: =$X$16/30 -> 0 | R4: =$X$19/30 -> 0 | S4: =$X$15/30 -> 0 | U4: =C4+B4+K4+L4+M4+O4+P4+Q4+R4+S4+T4+D4+E4+F4+G4+I4+H4 -> 0 | W4: Aliquota de Imposto | X4: 0.04 | AA4: =IFERROR(-(X3/(X6+X7)),"") | AB4: =IF($AA$4 > 12, "⭐ Excelente", IF($AA$4 >= 6, "✅ Saudável", IF($AA$4 < 5, "🛑 Perigo", "⚠️ Atenção"))) -> ⭐ Excelente
A5: 31 | O5: =$X$18/30 -> 0 | P5: =$X$17/30 -> 0 | Q5: =$X$16/30 -> 0 | R5: =$X$19/30 -> 0 | S5: =$X$15/30 -> 0 | U5: =C5+B5+K5+L5+M5+O5+P5+Q5+R5+S5+T5+D5+E5+F5+G5+I5+H5 -> 0 | W5: Total Gasto em armazenagem | X5: =SUM(B4:B33) -> 0
A6: 1 | O6: =$X$18/30 -> 0 | P6: =$X$17/30 -> 0 | Q6: =$X$16/30 -> 0 | R6: =$X$19/30 -> 0 | S6: =$X$15/30 -> 0 | U6: =C6+B6+K6+L6+M6+O6+P6+Q6+R6+S6+T6+D6+E6+F6+G6+I6+H6 -> 0 | W6: Ads Mercado Livre | X6: =SUM(K4:K33) -> 0 | AA6: Break-Even Point | AB6: =IFERROR(ABS(SUM(X14:X19)) / ((X3 - ABS(SUM(X5:X12))) / X3), "")
A7: 2 | O7: =$X$18/30 -> 0 | P7: =$X$17/30 -> 0 | Q7: =$X$16/30 -> 0 | R7: =$X$19/30 -> 0 | S7: =$X$15/30 -> 0 | U7: =C7+B7+K7+L7+M7+O7+P7+Q7+R7+S7+T7+D7+E7+F7+G7+I7+H7 -> 0 | W7: Ads Outras Plataformas avulsas
A8: 3 | O8: =$X$18/30 -> 0 | P8: =$X$17/30 -> 0 | Q8: =$X$16/30 -> 0 | R8: =$X$19/30 -> 0 | S8: =$X$15/30 -> 0 | U8: =C8+B8+K8+L8+M8+O8+P8+Q8+R8+S8+T8+D8+E8+F8+G8+I8+H8 -> 0 | W8: ticket médio mensal | X8: =(SUM(J4:J33))/31 -> 0
A9: 4 | O9: =$X$18/30 -> 0 | P9: =$X$17/30 -> 0 | Q9: =$X$16/30 -> 0 | R9: =$X$19/30 -> 0 | S9: =$X$15/30 -> 0 | U9: =C9+B9+K9+L9+M9+O9+P9+Q9+R9+S9+T9+D9+E9+F9+G9+I9+H9 -> 0 | W9: Custo com Produtos | X9: =SUM(L4:L33) -> 0
A10: 5 | O10: =$X$18/30 -> 0 | P10: =$X$17/30 -> 0 | Q10: =$X$16/30 -> 0 | R10: =$X$19/30 -> 0 | S10: =$X$15/30 -> 0 | U10: =C10+B10+K10+L10+M10+O10+P10+Q10+R10+S10+T10+D10+E10+F10+G10+I10+H10 -> 0 | W10: Tarifas Marketplaces | X10: =SUM(M4:M33) -> 0
A11: 6 | O11: =$X$18/30 -> 0 | P11: =$X$17/30 -> 0 | Q11: =$X$16/30 -> 0 | R11: =$X$19/30 -> 0 | S11: =$X$15/30 -> 0 | U11: =C11+B11+K11+L11+M11+O11+P11+Q11+R11+S11+T11+D11+E11+F11+G11+I11+H11 -> 0 | W11: Frete | X11: =SUM(N4:N34) -> 0
A12: 7 | O12: =$X$18/30 -> 0 | P12: =$X$17/30 -> 0 | Q12: =$X$16/30 -> 0 | R12: =$X$19/30 -> 0 | S12: =$X$15/30 -> 0 | U12: =C12+B12+K12+L12+M12+O12+P12+Q12+R12+S12+T12+D12+E12+F12+G12+I12+H12 -> 0 | W12: Imposto - DAS | X12: =-X3*X4 -> 0
A13: 8 | O13: =$X$18/30 -> 0 | P13: =$X$17/30 -> 0 | Q13: =$X$16/30 -> 0 | R13: =$X$19/30 -> 0 | S13: =$X$15/30 -> 0 | U13: =C13+B13+K13+L13+M13+O13+P13+Q13+R13+S13+T13+D13+E13+F13+G13+I13+H13 -> 0 | W13: Página Oficial Mercado Livre
A14: 9 | O14: =$X$18/30 -> 0 | P14: =$X$17/30 -> 0 | Q14: =$X$16/30 -> 0 | R14: =$X$19/30 -> 0 | S14: =$X$15/30 -> 0 | U14: =C14+B14+K14+L14+M14+O14+P14+Q14+R14+S14+T14+D14+E14+F14+G14+I14+H14 -> 0 | W14: Outras Taxas | X14: =SUM(T4:T33) -> 0
A15: 10 | O15: =$X$18/30 -> 0 | P15: =$X$17/30 -> 0 | Q15: =$X$16/30 -> 0 | R15: =$X$19/30 -> 0 | S15: =$X$15/30 -> 0 | U15: =C15+B15+K15+L15+M15+O15+P15+Q15+R15+S15+T15+D15+E15+F15+G15+I15+H15 -> 0 | W15: INSS
A16: 11 | O16: =$X$18/30 -> 0 | P16: =$X$17/30 -> 0 | Q16: =$X$16/30 -> 0 | R16: =$X$19/30 -> 0 | S16: =$X$15/30 -> 0 | U16: =C16+B16+K16+L16+M16+O16+P16+Q16+R16+S16+T16+D16+E16+F16+G16+I16+H16 -> 0 | W16: Contabilidade
A17: 12 | O17: =$X$18/30 -> 0 | P17: =$X$17/30 -> 0 | Q17: =$X$16/30 -> 0 | R17: =$X$19/30 -> 0 | S17: =$X$15/30 -> 0 | U17: =C17+B17+K17+L17+M17+O17+P17+Q17+R17+S17+T17+D17+E17+F17+G17+I17+H17 -> 0 | W17: Empréstimo | X17: 0
A18: 13 | O18: =$X$18/30 -> 0 | P18: =$X$17/30 -> 0 | Q18: =$X$16/30 -> 0 | R18: =$X$19/30 -> 0 | S18: =$X$15/30 -> 0 | U18: =C18+B18+K18+L18+M18+O18+P18+Q18+R18+S18+T18+D18+E18+F18+G18+I18+H18 -> 0 | W18: Pró Labore
A19: 14 | O19: =$X$18/30 -> 0 | P19: =$X$17/30 -> 0 | Q19: =$X$16/30 -> 0 | R19: =$X$19/30 -> 0 | S19: =$X$15/30 -> 0 | U19: =C19+B19+K19+L19+M19+O19+P19+Q19+R19+S19+T19+D19+E19+F19+G19+I19+H19 -> 0 | W19: Previdência Privada | X19: =(X18*20%)+(-X21*11%) -> 0
A20: 15 | O20: =$X$18/30 -> 0 | P20: =$X$17/30 -> 0 | Q20: =$X$16/30 -> 0 | R20: =$X$19/30 -> 0 | S20: =$X$15/30 -> 0 | U20: =C20+B20+K20+L20+M20+O20+P20+Q20+R20+S20+T20+D20+E20+F20+G20+I20+H20 -> 0 | W20: ERP Mensal
A21: 16 | O21: =$X$18/30 -> 0 | P21: =$X$17/30 -> 0 | Q21: =$X$16/30 -> 0 | R21: =$X$19/30 -> 0 | S21: =$X$15/30 -> 0 | U21: =C21+B21+K21+L21+M21+O21+P21+Q21+R21+S21+T21+D21+E21+F21+G21+I21+H21 -> 0 | W21: Lucro Bruto | X21: =X3+X5+X6+X9+X10+X12+X13+X15+X16+X17+X18+X20+X7 -> 0 | Y21: =Y3+Y5+Y6+Y7+Y9+Y10+Y12+Y13+Y15+Y16+Y17+Y18+Y20 -> 0
A22: 17 | O22: =$X$18/30 -> 0 | P22: =$X$17/30 -> 0 | Q22: =$X$16/30 -> 0 | R22: =$X$19/30 -> 0 | S22: =$X$15/30 -> 0 | U22: =C22+B22+K22+L22+M22+O22+P22+Q22+R22+S22+T22+D22+E22+F22+G22+I22+H22 -> 0 | W22: Lucro Liquido | X22: =X3+X5+X6+X7+X9+X10+X12+X13+X14+X15+X16+X17+X18+X19+X20 -> 0 | Y22: =Y3+Y5+Y6+Y7+Y9+Y10+Y12+Y13+Y15+Y16+Y17+Y18+Y19+Y20 -> 0
A23: 18 | O23: =$X$18/30 -> 0 | P23: =$X$17/30 -> 0 | Q23: =$X$16/30 -> 0 | R23: =$X$19/30 -> 0 | S23: =$X$15/30 -> 0 | U23: =C23+B23+K23+L23+M23+O23+P23+Q23+R23+S23+T23+D23+E23+F23+G23+I23+H23 -> 0
A24: 19 | O24: =$X$18/30 -> 0 | P24: =$X$17/30 -> 0 | Q24: =$X$16/30 -> 0 | R24: =$X$19/30 -> 0 | S24: =$X$15/30 -> 0 | U24: =C24+B24+K24+L24+M24+O24+P24+Q24+R24+S24+T24+D24+E24+F24+G24+I24+H24 -> 0 | W24: Fatura Mercado Livre | X24: =X6+X5+X14+X13 -> 0
A25: 20 | O25: =$X$18/30 -> 0 | P25: =$X$17/30 -> 0 | Q25: =$X$16/30 -> 0 | R25: =$X$19/30 -> 0 | S25: =$X$15/30 -> 0 | U25: =C25+B25+K25+L25+M25+O25+P25+Q25+R25+S25+T25+D25+E25+F25+G25+I25+H25 -> 0
A26: 21 | O26: =$X$18/30 -> 0 | P26: =$X$17/30 -> 0 | Q26: =$X$16/30 -> 0 | R26: =$X$19/30 -> 0 | S26: =$X$15/30 -> 0 | U26: =C26+B26+K26+L26+M26+O26+P26+Q26+R26+S26+T26+D26+E26+F26+G26+I26+H26 -> 0
A27: 22 | O27: =$X$18/30 -> 0 | P27: =$X$17/30 -> 0 | Q27: =$X$16/30 -> 0 | R27: =$X$19/30 -> 0 | S27: =$X$15/30 -> 0 | U27: =C27+B27+K27+L27+M27+O27+P27+Q27+R27+S27+T27+D27+E27+F27+G27+I27+H27 -> 0 | W27: DLR - Sócio | X27: =(X22*X30) -> 0 | Y27: =Y22*50% -> 0
A28: 23 | O28: =$X$18/30 -> 0 | P28: =$X$17/30 -> 0 | Q28: =$X$16/30 -> 0 | R28: =$X$19/30 -> 0 | S28: =$X$15/30 -> 0 | U28: =C28+B28+K28+L28+M28+O28+P28+Q28+R28+S28+T28+D28+E28+F28+G28+I28+H28 -> 0 | W28: Reinvestimento - Empresa | X28: =X22*X31 -> 0 | Y28: =Y22*X31 -> 0
A29: 24 | O29: =$X$18/30 -> 0 | P29: =$X$17/30 -> 0 | Q29: =$X$16/30 -> 0 | R29: =$X$19/30 -> 0 | S29: =$X$15/30 -> 0 | U29: =C29+B29+K29+L29+M29+O29+P29+Q29+R29+S29+T29+D29+E29+F29+G29+I29+H29 -> 0
A30: 25 | O30: =$X$18/30 -> 0 | P30: =$X$17/30 -> 0 | Q30: =$X$16/30 -> 0 | R30: =$X$19/30 -> 0 | S30: =$X$15/30 -> 0 | U30: =C30+B30+K30+L30+M30+O30+P30+Q30+R30+S30+T30+D30+E30+F30+G30+I30+H30 -> 0 | W30: % DLR do Sócio | X30: 0.5
A31: 26 | O31: =$X$18/30 -> 0 | P31: =$X$17/30 -> 0 | Q31: =$X$16/30 -> 0 | R31: =$X$19/30 -> 0 | S31: =$X$15/30 -> 0 | U31: =C31+B31+K31+L31+M31+O31+P31+Q31+R31+S31+T31+D31+E31+F31+G31+I31+H31 -> 0 | W31: Reinvestimento - Empresa | X31: 0.5
A32: 27 | O32: =$X$18/30 -> 0 | P32: =$X$17/30 -> 0 | Q32: =$X$16/30 -> 0 | R32: =$X$19/30 -> 0 | S32: =$X$15/30 -> 0 | U32: =C32+B32+K32+L32+M32+O32+P32+Q32+R32+S32+T32+D32+E32+F32+G32+I32+H32 -> 0 | Y32: Células que estão com formulas e não devem ser alteradas
A33: 28 | O33: =$X$18/30 -> 0 | P33: =$X$17/30 -> 0 | Q33: =$X$16/30 -> 0 | R33: =$X$19/30 -> 0 | S33: =$X$15/30 -> 0 | U33: =C33+B33+K33+L33+M33+O33+P33+Q33+R33+S33+T33+D33+E33+F33+G33+I33+H33 -> 0 | Y33: Células que devem ser imputados os valores manualmente
A34: 29 | O34: =$X$18/30 -> 0 | P34: =$X$17/30 -> 0 | Q34: =$X$16/30 -> 0 | R34: =$X$19/30 -> 0 | S34: =$X$15/30 -> 0 | U34: =C34+B34+K34+L34+M34+O34+P34+Q34+R34+S34+T34+D34+E34+F34+G34+I34+H34 -> 0
A36: Total | C36: =SUM(C4:C34) -> 0 | D36: =SUM(D4:D34) -> 0 | E36: =SUM(E4:E34) -> 0 | F36: =SUM(F4:F34) -> 0 | G36: =SUM(G4:G34) -> 0 | H36: =SUM(H4:H34) -> 0 | I36: =SUM(I4:I34) -> 0

Sheet Junho 2026
A1: Controle Mensal - Junho 2026
X2: Previsto | Y2: Real
A3: Dia | B3: Armazenagem | C3: Mercado Livre | D3: Magalu | E3: Casas Bahia | F3: Amazon | G3: Shopee | H3: TikTok | I3: Presencial | J3: Ticket Médio | K3: Ads | L3: Custo | M3: Tarifa | N3: Frete | O3: Salário | P3: Empréstimo | Q3: Contabilidade | R3: ERP | S3: INSS | T3: Outras Taxas | U3: Lucro Real do dia | W3: Faturamento | X3: =SUM(C35:I35) -> 0 | AA3: ROAS Atual | AB3: Objetivo
A4: 30 | O4: =$X$18/30 -> 0 | P4: =$X$17/30 -> 0 | Q4: =$X$16/30 -> 0 | R4: =$X$19/30 -> 0 | S4: =$X$15/30 -> 0 | U4: =C4+B4+K4+L4+M4+O4+P4+Q4+R4+S4+T4+D4+E4+F4+G4+I4+H4 -> 0 | W4: Aliquota de Imposto | X4: 0.04 | AA4: =IFERROR(-(X3/(X6+X7)),"") | AB4: =IF($AA$4 > 12, "⭐ Excelente", IF($AA$4 >= 6, "✅ Saudável", IF($AA$4 < 5, "🛑 Perigo", "⚠️ Atenção"))) -> ⭐ Excelente
A5: 31 | O5: =$X$18/30 -> 0 | P5: =$X$17/30 -> 0 | Q5: =$X$16/30 -> 0 | R5: =$X$19/30 -> 0 | S5: =$X$15/30 -> 0 | U5: =C5+B5+K5+L5+M5+O5+P5+Q5+R5+S5+T5+D5+E5+F5+G5+I5+H5 -> 0 | W5: Total Gasto em armazenagem | X5: =SUM(B4:B33) -> 0
A6: 1 | O6: =$X$18/30 -> 0 | P6: =$X$17/30 -> 0 | Q6: =$X$16/30 -> 0 | R6: =$X$19/30 -> 0 | S6: =$X$15/30 -> 0 | U6: =C6+B6+K6+L6+M6+O6+P6+Q6+R6+S6+T6+D6+E6+F6+G6+I6+H6 -> 0 | W6: Ads Mercado Livre | X6: =SUM(K4:K33) -> 0 | AA6: Break-Even Point | AB6: =IFERROR(ABS(SUM(X14:X19)) / ((X3 - ABS(SUM(X5:X12))) / X3), "")
A7: 2 | O7: =$X$18/30 -> 0 | P7: =$X$17/30 -> 0 | Q7: =$X$16/30 -> 0 | R7: =$X$19/30 -> 0 | S7: =$X$15/30 -> 0 | U7: =C7+B7+K7+L7+M7+O7+P7+Q7+R7+S7+T7+D7+E7+F7+G7+I7+H7 -> 0 | W7: Ads Outras Plataformas avulsas
A8: 3 | O8: =$X$18/30 -> 0 | P8: =$X$17/30 -> 0 | Q8: =$X$16/30 -> 0 | R8: =$X$19/30 -> 0 | S8: =$X$15/30 -> 0 | U8: =C8+B8+K8+L8+M8+O8+P8+Q8+R8+S8+T8+D8+E8+F8+G8+I8+H8 -> 0 | W8: ticket médio mensal | X8: =(SUM(J4:J33))/31 -> 0
A9: 4 | O9: =$X$18/30 -> 0 | P9: =$X$17/30 -> 0 | Q9: =$X$16/30 -> 0 | R9: =$X$19/30 -> 0 | S9: =$X$15/30 -> 0 | U9: =C9+B9+K9+L9+M9+O9+P9+Q9+R9+S9+T9+D9+E9+F9+G9+I9+H9 -> 0 | W9: Custo com Produtos | X9: =SUM(L4:L33) -> 0
A10: 5 | O10: =$X$18/30 -> 0 | P10: =$X$17/30 -> 0 | Q10: =$X$16/30 -> 0 | R10: =$X$19/30 -> 0 | S10: =$X$15/30 -> 0 | U10: =C10+B10+K10+L10+M10+O10+P10+Q10+R10+S10+T10+D10+E10+F10+G10+I10+H10 -> 0 | W10: Tarifas Marketplaces | X10: =SUM(M4:M33) -> 0
A11: 6 | O11: =$X$18/30 -> 0 | P11: =$X$17/30 -> 0 | Q11: =$X$16/30 -> 0 | R11: =$X$19/30 -> 0 | S11: =$X$15/30 -> 0 | U11: =C11+B11+K11+L11+M11+O11+P11+Q11+R11+S11+T11+D11+E11+F11+G11+I11+H11 -> 0 | W11: Frete | X11: =SUM(N4:N34) -> 0
A12: 7 | O12: =$X$18/30 -> 0 | P12: =$X$17/30 -> 0 | Q12: =$X$16/30 -> 0 | R12: =$X$19/30 -> 0 | S12: =$X$15/30 -> 0 | U12: =C12+B12+K12+L12+M12+O12+P12+Q12+R12+S12+T12+D12+E12+F12+G12+I12+H12 -> 0 | W12: Imposto - DAS | X12: =-X3*X4 -> 0
A13: 8 | O13: =$X$18/30 -> 0 | P13: =$X$17/30 -> 0 | Q13: =$X$16/30 -> 0 | R13: =$X$19/30 -> 0 | S13: =$X$15/30 -> 0 | U13: =C13+B13+K13+L13+M13+O13+P13+Q13+R13+S13+T13+D13+E13+F13+G13+I13+H13 -> 0 | W13: Página Oficial Mercado Livre
A14: 9 | O14: =$X$18/30 -> 0 | P14: =$X$17/30 -> 0 | Q14: =$X$16/30 -> 0 | R14: =$X$19/30 -> 0 | S14: =$X$15/30 -> 0 | U14: =C14+B14+K14+L14+M14+O14+P14+Q14+R14+S14+T14+D14+E14+F14+G14+I14+H14 -> 0 | W14: Outras Taxas | X14: =SUM(T4:T33) -> 0
A15: 10 | O15: =$X$18/30 -> 0 | P15: =$X$17/30 -> 0 | Q15: =$X$16/30 -> 0 | R15: =$X$19/30 -> 0 | S15: =$X$15/30 -> 0 | U15: =C15+B15+K15+L15+M15+O15+P15+Q15+R15+S15+T15+D15+E15+F15+G15+I15+H15 -> 0 | W15: INSS
A16: 11 | O16: =$X$18/30 -> 0 | P16: =$X$17/30 -> 0 | Q16: =$X$16/30 -> 0 | R16: =$X$19/30 -> 0 | S16: =$X$15/30 -> 0 | U16: =C16+B16+K16+L16+M16+O16+P16+Q16+R16+S16+T16+D16+E16+F16+G16+I16+H16 -> 0 | W16: Contabilidade
A17: 12 | O17: =$X$18/30 -> 0 | P17: =$X$17/30 -> 0 | Q17: =$X$16/30 -> 0 | R17: =$X$19/30 -> 0 | S17: =$X$15/30 -> 0 | U17: =C17+B17+K17+L17+M17+O17+P17+Q17+R17+S17+T17+D17+E17+F17+G17+I17+H17 -> 0 | W17: Empréstimo | X17: 0
A18: 13 | O18: =$X$18/30 -> 0 | P18: =$X$17/30 -> 0 | Q18: =$X$16/30 -> 0 | R18: =$X$19/30 -> 0 | S18: =$X$15/30 -> 0 | U18: =C18+B18+K18+L18+M18+O18+P18+Q18+R18+S18+T18+D18+E18+F18+G18+I18+H18 -> 0 | W18: Pró Labore
A19: 14 | O19: =$X$18/30 -> 0 | P19: =$X$17/30 -> 0 | Q19: =$X$16/30 -> 0 | R19: =$X$19/30 -> 0 | S19: =$X$15/30 -> 0 | U19: =C19+B19+K19+L19+M19+O19+P19+Q19+R19+S19+T19+D19+E19+F19+G19+I19+H19 -> 0 | W19: Previdência Privada | X19: =(X18*20%)+(-X21*11%) -> 0
A20: 15 | O20: =$X$18/30 -> 0 | P20: =$X$17/30 -> 0 | Q20: =$X$16/30 -> 0 | R20: =$X$19/30 -> 0 | S20: =$X$15/30 -> 0 | U20: =C20+B20+K20+L20+M20+O20+P20+Q20+R20+S20+T20+D20+E20+F20+G20+I20+H20 -> 0 | W20: ERP Mensal
A21: 16 | O21: =$X$18/30 -> 0 | P21: =$X$17/30 -> 0 | Q21: =$X$16/30 -> 0 | R21: =$X$19/30 -> 0 | S21: =$X$15/30 -> 0 | U21: =C21+B21+K21+L21+M21+O21+P21+Q21+R21+S21+T21+D21+E21+F21+G21+I21+H21 -> 0 | W21: Lucro Bruto | X21: =X3+X5+X6+X9+X10+X12+X13+X15+X16+X17+X18+X20+X7 -> 0 | Y21: =Y3+Y5+Y6+Y7+Y9+Y10+Y12+Y13+Y15+Y16+Y17+Y18+Y20 -> 0
A22: 17 | O22: =$X$18/30 -> 0 | P22: =$X$17/30 -> 0 | Q22: =$X$16/30 -> 0 | R22: =$X$19/30 -> 0 | S22: =$X$15/30 -> 0 | U22: =C22+B22+K22+L22+M22+O22+P22+Q22+R22+S22+T22+D22+E22+F22+G22+I22+H22 -> 0 | W22: Lucro Liquido | X22: =X3+X5+X6+X7+X9+X10+X12+X13+X14+X15+X16+X17+X18+X19+X20 -> 0 | Y22: =Y3+Y5+Y6+Y7+Y9+Y10+Y12+Y13+Y15+Y16+Y17+Y18+Y19+Y20 -> 0
A23: 18 | O23: =$X$18/30 -> 0 | P23: =$X$17/30 -> 0 | Q23: =$X$16/30 -> 0 | R23: =$X$19/30 -> 0 | S23: =$X$15/30 -> 0 | U23: =C23+B23+K23+L23+M23+O23+P23+Q23+R23+S23+T23+D23+E23+F23+G23+I23+H23 -> 0
A24: 19 | O24: =$X$18/30 -> 0 | P24: =$X$17/30 -> 0 | Q24: =$X$16/30 -> 0 | R24: =$X$19/30 -> 0 | S24: =$X$15/30 -> 0 | U24: =C24+B24+K24+L24+M24+O24+P24+Q24+R24+S24+T24+D24+E24+F24+G24+I24+H24 -> 0 | W24: Fatura Mercado Livre | X24: =X6+X5+X14+X13 -> 0
